[2024-06-25 18:03:19 +0800] [309662] [ERROR] Worker (pid:309664) was sent SIGHUP!
[2024-06-25 18:03:19 +0800] [309662] [ERROR] Worker (pid:309665) was sent SIGHUP!
[2024-06-25 18:03:19 +0800] [309662] [ERROR] Worker (pid:309713) was sent SIGHUP!
[2024-06-25 18:03:19 +0800] [309662] [ERROR] Worker (pid:309763) was sent SIGHUP!
[2024-06-25 18:03:19 +0800] [309662] [ERROR] Worker (pid:309663) was sent SIGHUP!
[2024-06-25 18:03:19 +0800] [309662] [ERROR] Worker (pid:309714) was sent SIGHUP!
[2024-06-25 18:03:19 +0800] [309662] [ERROR] Worker (pid:309715) was sent SIGHUP!
[2024-06-25 18:03:19 +0800] [309662] [ERROR] Worker (pid:309811) was sent SIGHUP!
[2024-06-25 21:25:30 +0800] [371698] [ERROR] Exception in worker process
Traceback (most recent call last):
  File "/data/biosoft/soft2024/conda/anaconda_23.4.7/envs/flask2024/lib/python3.9/site-packages/gunicorn/arbiter.py", line 609, in spawn_worker
    worker.init_process()
  File "/data/biosoft/soft2024/conda/anaconda_23.4.7/envs/flask2024/lib/python3.9/site-packages/gunicorn/workers/base.py", line 134, in init_process
    self.load_wsgi()
  File "/data/biosoft/soft2024/conda/anaconda_23.4.7/envs/flask2024/lib/python3.9/site-packages/gunicorn/workers/base.py", line 146, in load_wsgi
    self.wsgi = self.app.wsgi()
  File "/data/biosoft/soft2024/conda/anaconda_23.4.7/envs/flask2024/lib/python3.9/site-packages/gunicorn/app/base.py", line 67, in wsgi
    self.callable = self.load()
  File "/data/biosoft/soft2024/conda/anaconda_23.4.7/envs/flask2024/lib/python3.9/site-packages/gunicorn/app/wsgiapp.py", line 58, in load
    return self.load_wsgiapp()
  File "/data/biosoft/soft2024/conda/anaconda_23.4.7/envs/flask2024/lib/python3.9/site-packages/gunicorn/app/wsgiapp.py", line 48, in load_wsgiapp
    return util.import_app(self.app_uri)
  File "/data/biosoft/soft2024/conda/anaconda_23.4.7/envs/flask2024/lib/python3.9/site-packages/gunicorn/util.py", line 371, in import_app
    mod = importlib.import_module(module)
  File "/data/biosoft/soft2024/conda/anaconda_23.4.7/envs/flask2024/lib/python3.9/importlib/__init__.py", line 127, in import_module
    return _bootstrap._gcd_import(name[level:], package, level)
  File "<frozen importlib._bootstrap>", line 1030, in _gcd_import
  File "<frozen importlib._bootstrap>", line 1007, in _find_and_load
  File "<frozen importlib._bootstrap>", line 986, in _find_and_load_unlocked
  File "<frozen importlib._bootstrap>", line 680, in _load_unlocked
  File "<frozen importlib._bootstrap_external>", line 850, in exec_module
  File "<frozen importlib._bootstrap>", line 228, in _call_with_frames_removed
  File "/data/cailab/flask2024/wsgi.py", line 1, in <module>
    from demo import create_app
  File "/data/cailab/flask2024/demo/__init__.py", line 4, in <module>
    from flask import Flask
  File "/data/biosoft/soft2024/conda/anaconda_23.4.7/envs/flask2024/lib/python3.9/site-packages/flask/__init__.py", line 6, in <module>
    from .app import Flask as Flask
  File "/data/biosoft/soft2024/conda/anaconda_23.4.7/envs/flask2024/lib/python3.9/site-packages/flask/app.py", line 28, in <module>
    from . import cli
  File "/data/biosoft/soft2024/conda/anaconda_23.4.7/envs/flask2024/lib/python3.9/site-packages/flask/cli.py", line 18, in <module>
    from click.core import ParameterSource
ImportError: cannot import name 'ParameterSource' from 'click.core' (/data/biosoft/soft2024/conda/anaconda_23.4.7/envs/flask2024/lib/python3.9/site-packages/click/core.py)
[2024-06-25 21:25:30 +0800] [371697] [ERROR] Exception in worker process
Traceback (most recent call last):
  File "/data/biosoft/soft2024/conda/anaconda_23.4.7/envs/flask2024/lib/python3.9/site-packages/gunicorn/arbiter.py", line 609, in spawn_worker
    worker.init_process()
  File "/data/biosoft/soft2024/conda/anaconda_23.4.7/envs/flask2024/lib/python3.9/site-packages/gunicorn/workers/base.py", line 134, in init_process
    self.load_wsgi()
  File "/data/biosoft/soft2024/conda/anaconda_23.4.7/envs/flask2024/lib/python3.9/site-packages/gunicorn/workers/base.py", line 146, in load_wsgi
    self.wsgi = self.app.wsgi()
  File "/data/biosoft/soft2024/conda/anaconda_23.4.7/envs/flask2024/lib/python3.9/site-packages/gunicorn/app/base.py", line 67, in wsgi
    self.callable = self.load()
  File "/data/biosoft/soft2024/conda/anaconda_23.4.7/envs/flask2024/lib/python3.9/site-packages/gunicorn/app/wsgiapp.py", line 58, in load
    return self.load_wsgiapp()
  File "/data/biosoft/soft2024/conda/anaconda_23.4.7/envs/flask2024/lib/python3.9/site-packages/gunicorn/app/wsgiapp.py", line 48, in load_wsgiapp
    return util.import_app(self.app_uri)
  File "/data/biosoft/soft2024/conda/anaconda_23.4.7/envs/flask2024/lib/python3.9/site-packages/gunicorn/util.py", line 371, in import_app
    mod = importlib.import_module(module)
  File "/data/biosoft/soft2024/conda/anaconda_23.4.7/envs/flask2024/lib/python3.9/importlib/__init__.py", line 127, in import_module
    return _bootstrap._gcd_import(name[level:], package, level)
  File "<frozen importlib._bootstrap>", line 1030, in _gcd_import
  File "<frozen importlib._bootstrap>", line 1007, in _find_and_load
  File "<frozen importlib._bootstrap>", line 986, in _find_and_load_unlocked
  File "<frozen importlib._bootstrap>", line 680, in _load_unlocked
  File "<frozen importlib._bootstrap_external>", line 850, in exec_module
  File "<frozen importlib._bootstrap>", line 228, in _call_with_frames_removed
  File "/data/cailab/flask2024/wsgi.py", line 1, in <module>
    from demo import create_app
  File "/data/cailab/flask2024/demo/__init__.py", line 4, in <module>
    from flask import Flask
  File "/data/biosoft/soft2024/conda/anaconda_23.4.7/envs/flask2024/lib/python3.9/site-packages/flask/__init__.py", line 6, in <module>
    from .app import Flask as Flask
  File "/data/biosoft/soft2024/conda/anaconda_23.4.7/envs/flask2024/lib/python3.9/site-packages/flask/app.py", line 28, in <module>
    from . import cli
  File "/data/biosoft/soft2024/conda/anaconda_23.4.7/envs/flask2024/lib/python3.9/site-packages/flask/cli.py", line 18, in <module>
    from click.core import ParameterSource
ImportError: cannot import name 'ParameterSource' from 'click.core' (/data/biosoft/soft2024/conda/anaconda_23.4.7/envs/flask2024/lib/python3.9/site-packages/click/core.py)
[2024-06-25 21:25:30 +0800] [371695] [ERROR] Exception in worker process
Traceback (most recent call last):
  File "/data/biosoft/soft2024/conda/anaconda_23.4.7/envs/flask2024/lib/python3.9/site-packages/gunicorn/arbiter.py", line 609, in spawn_worker
    worker.init_process()
  File "/data/biosoft/soft2024/conda/anaconda_23.4.7/envs/flask2024/lib/python3.9/site-packages/gunicorn/workers/base.py", line 134, in init_process
    self.load_wsgi()
  File "/data/biosoft/soft2024/conda/anaconda_23.4.7/envs/flask2024/lib/python3.9/site-packages/gunicorn/workers/base.py", line 146, in load_wsgi
    self.wsgi = self.app.wsgi()
  File "/data/biosoft/soft2024/conda/anaconda_23.4.7/envs/flask2024/lib/python3.9/site-packages/gunicorn/app/base.py", line 67, in wsgi
    self.callable = self.load()
  File "/data/biosoft/soft2024/conda/anaconda_23.4.7/envs/flask2024/lib/python3.9/site-packages/gunicorn/app/wsgiapp.py", line 58, in load
    return self.load_wsgiapp()
  File "/data/biosoft/soft2024/conda/anaconda_23.4.7/envs/flask2024/lib/python3.9/site-packages/gunicorn/app/wsgiapp.py", line 48, in load_wsgiapp
    return util.import_app(self.app_uri)
  File "/data/biosoft/soft2024/conda/anaconda_23.4.7/envs/flask2024/lib/python3.9/site-packages/gunicorn/util.py", line 371, in import_app
    mod = importlib.import_module(module)
  File "/data/biosoft/soft2024/conda/anaconda_23.4.7/envs/flask2024/lib/python3.9/importlib/__init__.py", line 127, in import_module
    return _bootstrap._gcd_import(name[level:], package, level)
  File "<frozen importlib._bootstrap>", line 1030, in _gcd_import
  File "<frozen importlib._bootstrap>", line 1007, in _find_and_load
  File "<frozen importlib._bootstrap>", line 986, in _find_and_load_unlocked
  File "<frozen importlib._bootstrap>", line 680, in _load_unlocked
  File "<frozen importlib._bootstrap_external>", line 850, in exec_module
  File "<frozen importlib._bootstrap>", line 228, in _call_with_frames_removed
  File "/data/cailab/flask2024/wsgi.py", line 1, in <module>
    from demo import create_app
  File "/data/cailab/flask2024/demo/__init__.py", line 4, in <module>
    from flask import Flask
  File "/data/biosoft/soft2024/conda/anaconda_23.4.7/envs/flask2024/lib/python3.9/site-packages/flask/__init__.py", line 6, in <module>
    from .app import Flask as Flask
  File "/data/biosoft/soft2024/conda/anaconda_23.4.7/envs/flask2024/lib/python3.9/site-packages/flask/app.py", line 28, in <module>
    from . import cli
  File "/data/biosoft/soft2024/conda/anaconda_23.4.7/envs/flask2024/lib/python3.9/site-packages/flask/cli.py", line 18, in <module>
    from click.core import ParameterSource
ImportError: cannot import name 'ParameterSource' from 'click.core' (/data/biosoft/soft2024/conda/anaconda_23.4.7/envs/flask2024/lib/python3.9/site-packages/click/core.py)
[2024-06-25 21:25:30 +0800] [371696] [ERROR] Exception in worker process
Traceback (most recent call last):
  File "/data/biosoft/soft2024/conda/anaconda_23.4.7/envs/flask2024/lib/python3.9/site-packages/gunicorn/arbiter.py", line 609, in spawn_worker
    worker.init_process()
  File "/data/biosoft/soft2024/conda/anaconda_23.4.7/envs/flask2024/lib/python3.9/site-packages/gunicorn/workers/base.py", line 134, in init_process
    self.load_wsgi()
  File "/data/biosoft/soft2024/conda/anaconda_23.4.7/envs/flask2024/lib/python3.9/site-packages/gunicorn/workers/base.py", line 146, in load_wsgi
    self.wsgi = self.app.wsgi()
  File "/data/biosoft/soft2024/conda/anaconda_23.4.7/envs/flask2024/lib/python3.9/site-packages/gunicorn/app/base.py", line 67, in wsgi
    self.callable = self.load()
  File "/data/biosoft/soft2024/conda/anaconda_23.4.7/envs/flask2024/lib/python3.9/site-packages/gunicorn/app/wsgiapp.py", line 58, in load
    return self.load_wsgiapp()
  File "/data/biosoft/soft2024/conda/anaconda_23.4.7/envs/flask2024/lib/python3.9/site-packages/gunicorn/app/wsgiapp.py", line 48, in load_wsgiapp
    return util.import_app(self.app_uri)
  File "/data/biosoft/soft2024/conda/anaconda_23.4.7/envs/flask2024/lib/python3.9/site-packages/gunicorn/util.py", line 371, in import_app
    mod = importlib.import_module(module)
  File "/data/biosoft/soft2024/conda/anaconda_23.4.7/envs/flask2024/lib/python3.9/importlib/__init__.py", line 127, in import_module
    return _bootstrap._gcd_import(name[level:], package, level)
  File "<frozen importlib._bootstrap>", line 1030, in _gcd_import
  File "<frozen importlib._bootstrap>", line 1007, in _find_and_load
  File "<frozen importlib._bootstrap>", line 986, in _find_and_load_unlocked
  File "<frozen importlib._bootstrap>", line 680, in _load_unlocked
  File "<frozen importlib._bootstrap_external>", line 850, in exec_module
  File "<frozen importlib._bootstrap>", line 228, in _call_with_frames_removed
  File "/data/cailab/flask2024/wsgi.py", line 1, in <module>
    from demo import create_app
  File "/data/cailab/flask2024/demo/__init__.py", line 4, in <module>
    from flask import Flask
  File "/data/biosoft/soft2024/conda/anaconda_23.4.7/envs/flask2024/lib/python3.9/site-packages/flask/__init__.py", line 6, in <module>
    from .app import Flask as Flask
  File "/data/biosoft/soft2024/conda/anaconda_23.4.7/envs/flask2024/lib/python3.9/site-packages/flask/app.py", line 28, in <module>
    from . import cli
  File "/data/biosoft/soft2024/conda/anaconda_23.4.7/envs/flask2024/lib/python3.9/site-packages/flask/cli.py", line 18, in <module>
    from click.core import ParameterSource
ImportError: cannot import name 'ParameterSource' from 'click.core' (/data/biosoft/soft2024/conda/anaconda_23.4.7/envs/flask2024/lib/python3.9/site-packages/click/core.py)
[2024-06-25 21:25:30 +0800] [371694] [ERROR] Worker (pid:371698) exited with code 3
[2024-06-25 21:25:30 +0800] [371694] [ERROR] Worker (pid:371696) was sent SIGTERM!
[2024-06-25 21:25:30 +0800] [371694] [ERROR] Worker (pid:371697) was sent SIGTERM!
[2024-06-25 21:25:30 +0800] [371694] [ERROR] Worker (pid:371695) was sent SIGTERM!
[2024-06-25 21:25:30 +0800] [371699] [ERROR] Exception in worker process
Traceback (most recent call last):
  File "/data/biosoft/soft2024/conda/anaconda_23.4.7/envs/flask2024/lib/python3.9/site-packages/gunicorn/arbiter.py", line 609, in spawn_worker
    worker.init_process()
  File "/data/biosoft/soft2024/conda/anaconda_23.4.7/envs/flask2024/lib/python3.9/site-packages/gunicorn/workers/base.py", line 134, in init_process
    self.load_wsgi()
  File "/data/biosoft/soft2024/conda/anaconda_23.4.7/envs/flask2024/lib/python3.9/site-packages/gunicorn/workers/base.py", line 146, in load_wsgi
    self.wsgi = self.app.wsgi()
  File "/data/biosoft/soft2024/conda/anaconda_23.4.7/envs/flask2024/lib/python3.9/site-packages/gunicorn/app/base.py", line 67, in wsgi
    self.callable = self.load()
  File "/data/biosoft/soft2024/conda/anaconda_23.4.7/envs/flask2024/lib/python3.9/site-packages/gunicorn/app/wsgiapp.py", line 58, in load
    return self.load_wsgiapp()
  File "/data/biosoft/soft2024/conda/anaconda_23.4.7/envs/flask2024/lib/python3.9/site-packages/gunicorn/app/wsgiapp.py", line 48, in load_wsgiapp
    return util.import_app(self.app_uri)
  File "/data/biosoft/soft2024/conda/anaconda_23.4.7/envs/flask2024/lib/python3.9/site-packages/gunicorn/util.py", line 371, in import_app
    mod = importlib.import_module(module)
  File "/data/biosoft/soft2024/conda/anaconda_23.4.7/envs/flask2024/lib/python3.9/importlib/__init__.py", line 127, in import_module
    return _bootstrap._gcd_import(name[level:], package, level)
  File "<frozen importlib._bootstrap>", line 1030, in _gcd_import
  File "<frozen importlib._bootstrap>", line 1007, in _find_and_load
  File "<frozen importlib._bootstrap>", line 986, in _find_and_load_unlocked
  File "<frozen importlib._bootstrap>", line 680, in _load_unlocked
  File "<frozen importlib._bootstrap_external>", line 850, in exec_module
  File "<frozen importlib._bootstrap>", line 228, in _call_with_frames_removed
  File "/data/cailab/flask2024/wsgi.py", line 1, in <module>
    from demo import create_app
  File "/data/cailab/flask2024/demo/__init__.py", line 4, in <module>
    from flask import Flask
  File "/data/biosoft/soft2024/conda/anaconda_23.4.7/envs/flask2024/lib/python3.9/site-packages/flask/__init__.py", line 6, in <module>
    from .app import Flask as Flask
  File "/data/biosoft/soft2024/conda/anaconda_23.4.7/envs/flask2024/lib/python3.9/site-packages/flask/app.py", line 28, in <module>
    from . import cli
  File "/data/biosoft/soft2024/conda/anaconda_23.4.7/envs/flask2024/lib/python3.9/site-packages/flask/cli.py", line 18, in <module>
    from click.core import ParameterSource
ImportError: cannot import name 'ParameterSource' from 'click.core' (/data/biosoft/soft2024/conda/anaconda_23.4.7/envs/flask2024/lib/python3.9/site-packages/click/core.py)
[2024-06-25 21:25:30 +0800] [371694] [ERROR] Worker (pid:371699) exited with code 3
[2024-06-25 21:27:32 +0800] [372181] [ERROR] Exception in worker process
Traceback (most recent call last):
  File "/data/biosoft/soft2024/conda/anaconda_23.4.7/envs/flask2024/lib/python3.9/site-packages/gunicorn/arbiter.py", line 609, in spawn_worker
    worker.init_process()
  File "/data/biosoft/soft2024/conda/anaconda_23.4.7/envs/flask2024/lib/python3.9/site-packages/gunicorn/workers/base.py", line 134, in init_process
    self.load_wsgi()
  File "/data/biosoft/soft2024/conda/anaconda_23.4.7/envs/flask2024/lib/python3.9/site-packages/gunicorn/workers/base.py", line 146, in load_wsgi
    self.wsgi = self.app.wsgi()
  File "/data/biosoft/soft2024/conda/anaconda_23.4.7/envs/flask2024/lib/python3.9/site-packages/gunicorn/app/base.py", line 67, in wsgi
    self.callable = self.load()
  File "/data/biosoft/soft2024/conda/anaconda_23.4.7/envs/flask2024/lib/python3.9/site-packages/gunicorn/app/wsgiapp.py", line 58, in load
    return self.load_wsgiapp()
  File "/data/biosoft/soft2024/conda/anaconda_23.4.7/envs/flask2024/lib/python3.9/site-packages/gunicorn/app/wsgiapp.py", line 48, in load_wsgiapp
    return util.import_app(self.app_uri)
  File "/data/biosoft/soft2024/conda/anaconda_23.4.7/envs/flask2024/lib/python3.9/site-packages/gunicorn/util.py", line 371, in import_app
    mod = importlib.import_module(module)
  File "/data/biosoft/soft2024/conda/anaconda_23.4.7/envs/flask2024/lib/python3.9/importlib/__init__.py", line 127, in import_module
    return _bootstrap._gcd_import(name[level:], package, level)
  File "<frozen importlib._bootstrap>", line 1030, in _gcd_import
  File "<frozen importlib._bootstrap>", line 1007, in _find_and_load
  File "<frozen importlib._bootstrap>", line 986, in _find_and_load_unlocked
  File "<frozen importlib._bootstrap>", line 680, in _load_unlocked
  File "<frozen importlib._bootstrap_external>", line 850, in exec_module
  File "<frozen importlib._bootstrap>", line 228, in _call_with_frames_removed
  File "/data/cailab/flask2024/wsgi.py", line 1, in <module>
    from demo import create_app
  File "/data/cailab/flask2024/demo/__init__.py", line 4, in <module>
    from flask import Flask
  File "/data/biosoft/soft2024/conda/anaconda_23.4.7/envs/flask2024/lib/python3.9/site-packages/flask/__init__.py", line 6, in <module>
    from .app import Flask as Flask
  File "/data/biosoft/soft2024/conda/anaconda_23.4.7/envs/flask2024/lib/python3.9/site-packages/flask/app.py", line 28, in <module>
    from . import cli
  File "/data/biosoft/soft2024/conda/anaconda_23.4.7/envs/flask2024/lib/python3.9/site-packages/flask/cli.py", line 18, in <module>
    from click.core import ParameterSource
ImportError: cannot import name 'ParameterSource' from 'click.core' (/data/biosoft/soft2024/conda/anaconda_23.4.7/envs/flask2024/lib/python3.9/site-packages/click/core.py)
[2024-06-25 21:27:32 +0800] [372182] [ERROR] Exception in worker process
Traceback (most recent call last):
  File "/data/biosoft/soft2024/conda/anaconda_23.4.7/envs/flask2024/lib/python3.9/site-packages/gunicorn/arbiter.py", line 609, in spawn_worker
    worker.init_process()
  File "/data/biosoft/soft2024/conda/anaconda_23.4.7/envs/flask2024/lib/python3.9/site-packages/gunicorn/workers/base.py", line 134, in init_process
    self.load_wsgi()
  File "/data/biosoft/soft2024/conda/anaconda_23.4.7/envs/flask2024/lib/python3.9/site-packages/gunicorn/workers/base.py", line 146, in load_wsgi
    self.wsgi = self.app.wsgi()
  File "/data/biosoft/soft2024/conda/anaconda_23.4.7/envs/flask2024/lib/python3.9/site-packages/gunicorn/app/base.py", line 67, in wsgi
    self.callable = self.load()
  File "/data/biosoft/soft2024/conda/anaconda_23.4.7/envs/flask2024/lib/python3.9/site-packages/gunicorn/app/wsgiapp.py", line 58, in load
    return self.load_wsgiapp()
  File "/data/biosoft/soft2024/conda/anaconda_23.4.7/envs/flask2024/lib/python3.9/site-packages/gunicorn/app/wsgiapp.py", line 48, in load_wsgiapp
    return util.import_app(self.app_uri)
  File "/data/biosoft/soft2024/conda/anaconda_23.4.7/envs/flask2024/lib/python3.9/site-packages/gunicorn/util.py", line 371, in import_app
    mod = importlib.import_module(module)
  File "/data/biosoft/soft2024/conda/anaconda_23.4.7/envs/flask2024/lib/python3.9/importlib/__init__.py", line 127, in import_module
    return _bootstrap._gcd_import(name[level:], package, level)
  File "<frozen importlib._bootstrap>", line 1030, in _gcd_import
  File "<frozen importlib._bootstrap>", line 1007, in _find_and_load
  File "<frozen importlib._bootstrap>", line 986, in _find_and_load_unlocked
  File "<frozen importlib._bootstrap>", line 680, in _load_unlocked
  File "<frozen importlib._bootstrap_external>", line 850, in exec_module
  File "<frozen importlib._bootstrap>", line 228, in _call_with_frames_removed
  File "/data/cailab/flask2024/wsgi.py", line 1, in <module>
    from demo import create_app
  File "/data/cailab/flask2024/demo/__init__.py", line 4, in <module>
    from flask import Flask
  File "/data/biosoft/soft2024/conda/anaconda_23.4.7/envs/flask2024/lib/python3.9/site-packages/flask/__init__.py", line 6, in <module>
    from .app import Flask as Flask
  File "/data/biosoft/soft2024/conda/anaconda_23.4.7/envs/flask2024/lib/python3.9/site-packages/flask/app.py", line 28, in <module>
    from . import cli
  File "/data/biosoft/soft2024/conda/anaconda_23.4.7/envs/flask2024/lib/python3.9/site-packages/flask/cli.py", line 18, in <module>
    from click.core import ParameterSource
ImportError: cannot import name 'ParameterSource' from 'click.core' (/data/biosoft/soft2024/conda/anaconda_23.4.7/envs/flask2024/lib/python3.9/site-packages/click/core.py)
[2024-06-25 21:27:32 +0800] [372180] [ERROR] Worker (pid:372181) exited with code 3
[2024-06-25 21:27:32 +0800] [372180] [ERROR] Worker (pid:372182) was sent SIGTERM!
[2024-06-25 21:27:32 +0800] [372183] [ERROR] Exception in worker process
Traceback (most recent call last):
  File "/data/biosoft/soft2024/conda/anaconda_23.4.7/envs/flask2024/lib/python3.9/site-packages/gunicorn/arbiter.py", line 609, in spawn_worker
    worker.init_process()
  File "/data/biosoft/soft2024/conda/anaconda_23.4.7/envs/flask2024/lib/python3.9/site-packages/gunicorn/workers/base.py", line 134, in init_process
    self.load_wsgi()
  File "/data/biosoft/soft2024/conda/anaconda_23.4.7/envs/flask2024/lib/python3.9/site-packages/gunicorn/workers/base.py", line 146, in load_wsgi
    self.wsgi = self.app.wsgi()
  File "/data/biosoft/soft2024/conda/anaconda_23.4.7/envs/flask2024/lib/python3.9/site-packages/gunicorn/app/base.py", line 67, in wsgi
    self.callable = self.load()
  File "/data/biosoft/soft2024/conda/anaconda_23.4.7/envs/flask2024/lib/python3.9/site-packages/gunicorn/app/wsgiapp.py", line 58, in load
    return self.load_wsgiapp()
  File "/data/biosoft/soft2024/conda/anaconda_23.4.7/envs/flask2024/lib/python3.9/site-packages/gunicorn/app/wsgiapp.py", line 48, in load_wsgiapp
    return util.import_app(self.app_uri)
  File "/data/biosoft/soft2024/conda/anaconda_23.4.7/envs/flask2024/lib/python3.9/site-packages/gunicorn/util.py", line 371, in import_app
    mod = importlib.import_module(module)
  File "/data/biosoft/soft2024/conda/anaconda_23.4.7/envs/flask2024/lib/python3.9/importlib/__init__.py", line 127, in import_module
    return _bootstrap._gcd_import(name[level:], package, level)
  File "<frozen importlib._bootstrap>", line 1030, in _gcd_import
  File "<frozen importlib._bootstrap>", line 1007, in _find_and_load
  File "<frozen importlib._bootstrap>", line 986, in _find_and_load_unlocked
  File "<frozen importlib._bootstrap>", line 680, in _load_unlocked
  File "<frozen importlib._bootstrap_external>", line 850, in exec_module
  File "<frozen importlib._bootstrap>", line 228, in _call_with_frames_removed
  File "/data/cailab/flask2024/wsgi.py", line 1, in <module>
    from demo import create_app
  File "/data/cailab/flask2024/demo/__init__.py", line 4, in <module>
    from flask import Flask
  File "/data/biosoft/soft2024/conda/anaconda_23.4.7/envs/flask2024/lib/python3.9/site-packages/flask/__init__.py", line 6, in <module>
    from .app import Flask as Flask
  File "/data/biosoft/soft2024/conda/anaconda_23.4.7/envs/flask2024/lib/python3.9/site-packages/flask/app.py", line 28, in <module>
    from . import cli
  File "/data/biosoft/soft2024/conda/anaconda_23.4.7/envs/flask2024/lib/python3.9/site-packages/flask/cli.py", line 18, in <module>
    from click.core import ParameterSource
ImportError: cannot import name 'ParameterSource' from 'click.core' (/data/biosoft/soft2024/conda/anaconda_23.4.7/envs/flask2024/lib/python3.9/site-packages/click/core.py)
[2024-06-25 21:27:32 +0800] [372180] [ERROR] Worker (pid:372183) exited with code 3
[2024-06-25 21:28:59 +0800] [372523] [ERROR] Exception in worker process
Traceback (most recent call last):
  File "/data/biosoft/soft2024/conda/anaconda_23.4.7/envs/flask2024/lib/python3.9/site-packages/gunicorn/arbiter.py", line 609, in spawn_worker
    worker.init_process()
  File "/data/biosoft/soft2024/conda/anaconda_23.4.7/envs/flask2024/lib/python3.9/site-packages/gunicorn/workers/base.py", line 134, in init_process
    self.load_wsgi()
  File "/data/biosoft/soft2024/conda/anaconda_23.4.7/envs/flask2024/lib/python3.9/site-packages/gunicorn/workers/base.py", line 146, in load_wsgi
    self.wsgi = self.app.wsgi()
  File "/data/biosoft/soft2024/conda/anaconda_23.4.7/envs/flask2024/lib/python3.9/site-packages/gunicorn/app/base.py", line 67, in wsgi
    self.callable = self.load()
  File "/data/biosoft/soft2024/conda/anaconda_23.4.7/envs/flask2024/lib/python3.9/site-packages/gunicorn/app/wsgiapp.py", line 58, in load
    return self.load_wsgiapp()
  File "/data/biosoft/soft2024/conda/anaconda_23.4.7/envs/flask2024/lib/python3.9/site-packages/gunicorn/app/wsgiapp.py", line 48, in load_wsgiapp
    return util.import_app(self.app_uri)
  File "/data/biosoft/soft2024/conda/anaconda_23.4.7/envs/flask2024/lib/python3.9/site-packages/gunicorn/util.py", line 371, in import_app
    mod = importlib.import_module(module)
  File "/data/biosoft/soft2024/conda/anaconda_23.4.7/envs/flask2024/lib/python3.9/importlib/__init__.py", line 127, in import_module
    return _bootstrap._gcd_import(name[level:], package, level)
  File "<frozen importlib._bootstrap>", line 1030, in _gcd_import
  File "<frozen importlib._bootstrap>", line 1007, in _find_and_load
  File "<frozen importlib._bootstrap>", line 986, in _find_and_load_unlocked
  File "<frozen importlib._bootstrap>", line 680, in _load_unlocked
  File "<frozen importlib._bootstrap_external>", line 850, in exec_module
  File "<frozen importlib._bootstrap>", line 228, in _call_with_frames_removed
  File "/data/cailab/flask2024/wsgi.py", line 1, in <module>
    from demo import create_app
  File "/data/cailab/flask2024/demo/__init__.py", line 6, in <module>
    from demo.blueprint.biology import biology
  File "/data/cailab/flask2024/demo/blueprint/biology.py", line 25, in <module>
    from demo.blueprint.modules.core import PipelineForm
  File "/data/cailab/flask2024/demo/blueprint/modules/core.py", line 14, in <module>
    globals()[name+"Form_default"] = getattr(module, name+"Form_default")
AttributeError: module 'demo.blueprint.modules.pipeline_CAPS' has no attribute 'CAPSForm_default'
[2024-06-25 21:28:59 +0800] [372572] [ERROR] Exception in worker process
Traceback (most recent call last):
  File "/data/biosoft/soft2024/conda/anaconda_23.4.7/envs/flask2024/lib/python3.9/site-packages/gunicorn/arbiter.py", line 609, in spawn_worker
    worker.init_process()
  File "/data/biosoft/soft2024/conda/anaconda_23.4.7/envs/flask2024/lib/python3.9/site-packages/gunicorn/workers/base.py", line 134, in init_process
    self.load_wsgi()
  File "/data/biosoft/soft2024/conda/anaconda_23.4.7/envs/flask2024/lib/python3.9/site-packages/gunicorn/workers/base.py", line 146, in load_wsgi
    self.wsgi = self.app.wsgi()
  File "/data/biosoft/soft2024/conda/anaconda_23.4.7/envs/flask2024/lib/python3.9/site-packages/gunicorn/app/base.py", line 67, in wsgi
    self.callable = self.load()
  File "/data/biosoft/soft2024/conda/anaconda_23.4.7/envs/flask2024/lib/python3.9/site-packages/gunicorn/app/wsgiapp.py", line 58, in load
    return self.load_wsgiapp()
  File "/data/biosoft/soft2024/conda/anaconda_23.4.7/envs/flask2024/lib/python3.9/site-packages/gunicorn/app/wsgiapp.py", line 48, in load_wsgiapp
    return util.import_app(self.app_uri)
  File "/data/biosoft/soft2024/conda/anaconda_23.4.7/envs/flask2024/lib/python3.9/site-packages/gunicorn/util.py", line 371, in import_app
    mod = importlib.import_module(module)
  File "/data/biosoft/soft2024/conda/anaconda_23.4.7/envs/flask2024/lib/python3.9/importlib/__init__.py", line 127, in import_module
    return _bootstrap._gcd_import(name[level:], package, level)
  File "<frozen importlib._bootstrap>", line 1030, in _gcd_import
  File "<frozen importlib._bootstrap>", line 1007, in _find_and_load
  File "<frozen importlib._bootstrap>", line 986, in _find_and_load_unlocked
  File "<frozen importlib._bootstrap>", line 680, in _load_unlocked
  File "<frozen importlib._bootstrap_external>", line 850, in exec_module
  File "<frozen importlib._bootstrap>", line 228, in _call_with_frames_removed
  File "/data/cailab/flask2024/wsgi.py", line 1, in <module>
    from demo import create_app
  File "/data/cailab/flask2024/demo/__init__.py", line 6, in <module>
    from demo.blueprint.biology import biology
  File "/data/cailab/flask2024/demo/blueprint/biology.py", line 25, in <module>
    from demo.blueprint.modules.core import PipelineForm
  File "/data/cailab/flask2024/demo/blueprint/modules/core.py", line 14, in <module>
    globals()[name+"Form_default"] = getattr(module, name+"Form_default")
AttributeError: module 'demo.blueprint.modules.pipeline_CAPS' has no attribute 'CAPSForm_default'
[2024-06-25 21:28:59 +0800] [372716] [ERROR] Exception in worker process
Traceback (most recent call last):
  File "/data/biosoft/soft2024/conda/anaconda_23.4.7/envs/flask2024/lib/python3.9/site-packages/gunicorn/arbiter.py", line 609, in spawn_worker
    worker.init_process()
  File "/data/biosoft/soft2024/conda/anaconda_23.4.7/envs/flask2024/lib/python3.9/site-packages/gunicorn/workers/base.py", line 134, in init_process
    self.load_wsgi()
  File "/data/biosoft/soft2024/conda/anaconda_23.4.7/envs/flask2024/lib/python3.9/site-packages/gunicorn/workers/base.py", line 146, in load_wsgi
    self.wsgi = self.app.wsgi()
  File "/data/biosoft/soft2024/conda/anaconda_23.4.7/envs/flask2024/lib/python3.9/site-packages/gunicorn/app/base.py", line 67, in wsgi
    self.callable = self.load()
  File "/data/biosoft/soft2024/conda/anaconda_23.4.7/envs/flask2024/lib/python3.9/site-packages/gunicorn/app/wsgiapp.py", line 58, in load
    return self.load_wsgiapp()
  File "/data/biosoft/soft2024/conda/anaconda_23.4.7/envs/flask2024/lib/python3.9/site-packages/gunicorn/app/wsgiapp.py", line 48, in load_wsgiapp
    return util.import_app(self.app_uri)
  File "/data/biosoft/soft2024/conda/anaconda_23.4.7/envs/flask2024/lib/python3.9/site-packages/gunicorn/util.py", line 371, in import_app
    mod = importlib.import_module(module)
  File "/data/biosoft/soft2024/conda/anaconda_23.4.7/envs/flask2024/lib/python3.9/importlib/__init__.py", line 127, in import_module
    return _bootstrap._gcd_import(name[level:], package, level)
  File "<frozen importlib._bootstrap>", line 1030, in _gcd_import
  File "<frozen importlib._bootstrap>", line 1007, in _find_and_load
  File "<frozen importlib._bootstrap>", line 986, in _find_and_load_unlocked
  File "<frozen importlib._bootstrap>", line 680, in _load_unlocked
  File "<frozen importlib._bootstrap_external>", line 850, in exec_module
  File "<frozen importlib._bootstrap>", line 228, in _call_with_frames_removed
  File "/data/cailab/flask2024/wsgi.py", line 1, in <module>
    from demo import create_app
  File "/data/cailab/flask2024/demo/__init__.py", line 6, in <module>
    from demo.blueprint.biology import biology
  File "/data/cailab/flask2024/demo/blueprint/biology.py", line 25, in <module>
    from demo.blueprint.modules.core import PipelineForm
  File "/data/cailab/flask2024/demo/blueprint/modules/core.py", line 14, in <module>
    globals()[name+"Form_default"] = getattr(module, name+"Form_default")
AttributeError: module 'demo.blueprint.modules.pipeline_CAPS' has no attribute 'CAPSForm_default'
[2024-06-25 21:28:59 +0800] [372718] [ERROR] Exception in worker process
Traceback (most recent call last):
  File "/data/biosoft/soft2024/conda/anaconda_23.4.7/envs/flask2024/lib/python3.9/site-packages/gunicorn/arbiter.py", line 609, in spawn_worker
    worker.init_process()
  File "/data/biosoft/soft2024/conda/anaconda_23.4.7/envs/flask2024/lib/python3.9/site-packages/gunicorn/workers/base.py", line 134, in init_process
    self.load_wsgi()
  File "/data/biosoft/soft2024/conda/anaconda_23.4.7/envs/flask2024/lib/python3.9/site-packages/gunicorn/workers/base.py", line 146, in load_wsgi
    self.wsgi = self.app.wsgi()
  File "/data/biosoft/soft2024/conda/anaconda_23.4.7/envs/flask2024/lib/python3.9/site-packages/gunicorn/app/base.py", line 67, in wsgi
    self.callable = self.load()
  File "/data/biosoft/soft2024/conda/anaconda_23.4.7/envs/flask2024/lib/python3.9/site-packages/gunicorn/app/wsgiapp.py", line 58, in load
    return self.load_wsgiapp()
  File "/data/biosoft/soft2024/conda/anaconda_23.4.7/envs/flask2024/lib/python3.9/site-packages/gunicorn/app/wsgiapp.py", line 48, in load_wsgiapp
    return util.import_app(self.app_uri)
  File "/data/biosoft/soft2024/conda/anaconda_23.4.7/envs/flask2024/lib/python3.9/site-packages/gunicorn/util.py", line 371, in import_app
    mod = importlib.import_module(module)
  File "/data/biosoft/soft2024/conda/anaconda_23.4.7/envs/flask2024/lib/python3.9/importlib/__init__.py", line 127, in import_module
    return _bootstrap._gcd_import(name[level:], package, level)
  File "<frozen importlib._bootstrap>", line 1030, in _gcd_import
  File "<frozen importlib._bootstrap>", line 1007, in _find_and_load
  File "<frozen importlib._bootstrap>", line 986, in _find_and_load_unlocked
  File "<frozen importlib._bootstrap>", line 680, in _load_unlocked
  File "<frozen importlib._bootstrap_external>", line 850, in exec_module
  File "<frozen importlib._bootstrap>", line 228, in _call_with_frames_removed
  File "/data/cailab/flask2024/wsgi.py", line 1, in <module>
    from demo import create_app
  File "/data/cailab/flask2024/demo/__init__.py", line 6, in <module>
    from demo.blueprint.biology import biology
  File "/data/cailab/flask2024/demo/blueprint/biology.py", line 25, in <module>
    from demo.blueprint.modules.core import PipelineForm
  File "/data/cailab/flask2024/demo/blueprint/modules/core.py", line 14, in <module>
    globals()[name+"Form_default"] = getattr(module, name+"Form_default")
AttributeError: module 'demo.blueprint.modules.pipeline_CAPS' has no attribute 'CAPSForm_default'
[2024-06-25 21:28:59 +0800] [372577] [ERROR] Exception in worker process
Traceback (most recent call last):
  File "/data/biosoft/soft2024/conda/anaconda_23.4.7/envs/flask2024/lib/python3.9/site-packages/gunicorn/arbiter.py", line 609, in spawn_worker
    worker.init_process()
  File "/data/biosoft/soft2024/conda/anaconda_23.4.7/envs/flask2024/lib/python3.9/site-packages/gunicorn/workers/base.py", line 134, in init_process
    self.load_wsgi()
  File "/data/biosoft/soft2024/conda/anaconda_23.4.7/envs/flask2024/lib/python3.9/site-packages/gunicorn/workers/base.py", line 146, in load_wsgi
    self.wsgi = self.app.wsgi()
  File "/data/biosoft/soft2024/conda/anaconda_23.4.7/envs/flask2024/lib/python3.9/site-packages/gunicorn/app/base.py", line 67, in wsgi
    self.callable = self.load()
  File "/data/biosoft/soft2024/conda/anaconda_23.4.7/envs/flask2024/lib/python3.9/site-packages/gunicorn/app/wsgiapp.py", line 58, in load
    return self.load_wsgiapp()
  File "/data/biosoft/soft2024/conda/anaconda_23.4.7/envs/flask2024/lib/python3.9/site-packages/gunicorn/app/wsgiapp.py", line 48, in load_wsgiapp
    return util.import_app(self.app_uri)
  File "/data/biosoft/soft2024/conda/anaconda_23.4.7/envs/flask2024/lib/python3.9/site-packages/gunicorn/util.py", line 371, in import_app
    mod = importlib.import_module(module)
  File "/data/biosoft/soft2024/conda/anaconda_23.4.7/envs/flask2024/lib/python3.9/importlib/__init__.py", line 127, in import_module
    return _bootstrap._gcd_import(name[level:], package, level)
  File "<frozen importlib._bootstrap>", line 1030, in _gcd_import
  File "<frozen importlib._bootstrap>", line 1007, in _find_and_load
  File "<frozen importlib._bootstrap>", line 986, in _find_and_load_unlocked
  File "<frozen importlib._bootstrap>", line 680, in _load_unlocked
  File "<frozen importlib._bootstrap_external>", line 850, in exec_module
  File "<frozen importlib._bootstrap>", line 228, in _call_with_frames_removed
  File "/data/cailab/flask2024/wsgi.py", line 1, in <module>
    from demo import create_app
  File "/data/cailab/flask2024/demo/__init__.py", line 6, in <module>
    from demo.blueprint.biology import biology
  File "/data/cailab/flask2024/demo/blueprint/biology.py", line 25, in <module>
    from demo.blueprint.modules.core import PipelineForm
  File "/data/cailab/flask2024/demo/blueprint/modules/core.py", line 14, in <module>
    globals()[name+"Form_default"] = getattr(module, name+"Form_default")
AttributeError: module 'demo.blueprint.modules.pipeline_CAPS' has no attribute 'CAPSForm_default'
[2024-06-25 21:28:59 +0800] [372524] [ERROR] Exception in worker process
Traceback (most recent call last):
  File "/data/biosoft/soft2024/conda/anaconda_23.4.7/envs/flask2024/lib/python3.9/site-packages/gunicorn/arbiter.py", line 609, in spawn_worker
    worker.init_process()
  File "/data/biosoft/soft2024/conda/anaconda_23.4.7/envs/flask2024/lib/python3.9/site-packages/gunicorn/workers/base.py", line 134, in init_process
    self.load_wsgi()
  File "/data/biosoft/soft2024/conda/anaconda_23.4.7/envs/flask2024/lib/python3.9/site-packages/gunicorn/workers/base.py", line 146, in load_wsgi
    self.wsgi = self.app.wsgi()
  File "/data/biosoft/soft2024/conda/anaconda_23.4.7/envs/flask2024/lib/python3.9/site-packages/gunicorn/app/base.py", line 67, in wsgi
    self.callable = self.load()
  File "/data/biosoft/soft2024/conda/anaconda_23.4.7/envs/flask2024/lib/python3.9/site-packages/gunicorn/app/wsgiapp.py", line 58, in load
    return self.load_wsgiapp()
  File "/data/biosoft/soft2024/conda/anaconda_23.4.7/envs/flask2024/lib/python3.9/site-packages/gunicorn/app/wsgiapp.py", line 48, in load_wsgiapp
    return util.import_app(self.app_uri)
  File "/data/biosoft/soft2024/conda/anaconda_23.4.7/envs/flask2024/lib/python3.9/site-packages/gunicorn/util.py", line 371, in import_app
    mod = importlib.import_module(module)
  File "/data/biosoft/soft2024/conda/anaconda_23.4.7/envs/flask2024/lib/python3.9/importlib/__init__.py", line 127, in import_module
    return _bootstrap._gcd_import(name[level:], package, level)
  File "<frozen importlib._bootstrap>", line 1030, in _gcd_import
  File "<frozen importlib._bootstrap>", line 1007, in _find_and_load
  File "<frozen importlib._bootstrap>", line 986, in _find_and_load_unlocked
  File "<frozen importlib._bootstrap>", line 680, in _load_unlocked
  File "<frozen importlib._bootstrap_external>", line 850, in exec_module
  File "<frozen importlib._bootstrap>", line 228, in _call_with_frames_removed
  File "/data/cailab/flask2024/wsgi.py", line 1, in <module>
    from demo import create_app
  File "/data/cailab/flask2024/demo/__init__.py", line 6, in <module>
    from demo.blueprint.biology import biology
  File "/data/cailab/flask2024/demo/blueprint/biology.py", line 25, in <module>
    from demo.blueprint.modules.core import PipelineForm
  File "/data/cailab/flask2024/demo/blueprint/modules/core.py", line 14, in <module>
    globals()[name+"Form_default"] = getattr(module, name+"Form_default")
AttributeError: module 'demo.blueprint.modules.pipeline_CAPS' has no attribute 'CAPSForm_default'
[2024-06-25 21:28:59 +0800] [372717] [ERROR] Exception in worker process
Traceback (most recent call last):
  File "/data/biosoft/soft2024/conda/anaconda_23.4.7/envs/flask2024/lib/python3.9/site-packages/gunicorn/arbiter.py", line 609, in spawn_worker
    worker.init_process()
  File "/data/biosoft/soft2024/conda/anaconda_23.4.7/envs/flask2024/lib/python3.9/site-packages/gunicorn/workers/base.py", line 134, in init_process
    self.load_wsgi()
  File "/data/biosoft/soft2024/conda/anaconda_23.4.7/envs/flask2024/lib/python3.9/site-packages/gunicorn/workers/base.py", line 146, in load_wsgi
    self.wsgi = self.app.wsgi()
  File "/data/biosoft/soft2024/conda/anaconda_23.4.7/envs/flask2024/lib/python3.9/site-packages/gunicorn/app/base.py", line 67, in wsgi
    self.callable = self.load()
  File "/data/biosoft/soft2024/conda/anaconda_23.4.7/envs/flask2024/lib/python3.9/site-packages/gunicorn/app/wsgiapp.py", line 58, in load
    return self.load_wsgiapp()
  File "/data/biosoft/soft2024/conda/anaconda_23.4.7/envs/flask2024/lib/python3.9/site-packages/gunicorn/app/wsgiapp.py", line 48, in load_wsgiapp
    return util.import_app(self.app_uri)
  File "/data/biosoft/soft2024/conda/anaconda_23.4.7/envs/flask2024/lib/python3.9/site-packages/gunicorn/util.py", line 371, in import_app
    mod = importlib.import_module(module)
  File "/data/biosoft/soft2024/conda/anaconda_23.4.7/envs/flask2024/lib/python3.9/importlib/__init__.py", line 127, in import_module
    return _bootstrap._gcd_import(name[level:], package, level)
  File "<frozen importlib._bootstrap>", line 1030, in _gcd_import
  File "<frozen importlib._bootstrap>", line 1007, in _find_and_load
  File "<frozen importlib._bootstrap>", line 986, in _find_and_load_unlocked
  File "<frozen importlib._bootstrap>", line 680, in _load_unlocked
  File "<frozen importlib._bootstrap_external>", line 850, in exec_module
  File "<frozen importlib._bootstrap>", line 228, in _call_with_frames_removed
  File "/data/cailab/flask2024/wsgi.py", line 1, in <module>
    from demo import create_app
  File "/data/cailab/flask2024/demo/__init__.py", line 6, in <module>
    from demo.blueprint.biology import biology
  File "/data/cailab/flask2024/demo/blueprint/biology.py", line 25, in <module>
    from demo.blueprint.modules.core import PipelineForm
  File "/data/cailab/flask2024/demo/blueprint/modules/core.py", line 14, in <module>
    globals()[name+"Form_default"] = getattr(module, name+"Form_default")
AttributeError: module 'demo.blueprint.modules.pipeline_CAPS' has no attribute 'CAPSForm_default'
[2024-06-25 21:28:59 +0800] [372621] [ERROR] Exception in worker process
Traceback (most recent call last):
  File "/data/biosoft/soft2024/conda/anaconda_23.4.7/envs/flask2024/lib/python3.9/site-packages/gunicorn/arbiter.py", line 609, in spawn_worker
    worker.init_process()
  File "/data/biosoft/soft2024/conda/anaconda_23.4.7/envs/flask2024/lib/python3.9/site-packages/gunicorn/workers/base.py", line 134, in init_process
    self.load_wsgi()
  File "/data/biosoft/soft2024/conda/anaconda_23.4.7/envs/flask2024/lib/python3.9/site-packages/gunicorn/workers/base.py", line 146, in load_wsgi
    self.wsgi = self.app.wsgi()
  File "/data/biosoft/soft2024/conda/anaconda_23.4.7/envs/flask2024/lib/python3.9/site-packages/gunicorn/app/base.py", line 67, in wsgi
    self.callable = self.load()
  File "/data/biosoft/soft2024/conda/anaconda_23.4.7/envs/flask2024/lib/python3.9/site-packages/gunicorn/app/wsgiapp.py", line 58, in load
    return self.load_wsgiapp()
  File "/data/biosoft/soft2024/conda/anaconda_23.4.7/envs/flask2024/lib/python3.9/site-packages/gunicorn/app/wsgiapp.py", line 48, in load_wsgiapp
    return util.import_app(self.app_uri)
  File "/data/biosoft/soft2024/conda/anaconda_23.4.7/envs/flask2024/lib/python3.9/site-packages/gunicorn/util.py", line 371, in import_app
    mod = importlib.import_module(module)
  File "/data/biosoft/soft2024/conda/anaconda_23.4.7/envs/flask2024/lib/python3.9/importlib/__init__.py", line 127, in import_module
    return _bootstrap._gcd_import(name[level:], package, level)
  File "<frozen importlib._bootstrap>", line 1030, in _gcd_import
  File "<frozen importlib._bootstrap>", line 1007, in _find_and_load
  File "<frozen importlib._bootstrap>", line 986, in _find_and_load_unlocked
  File "<frozen importlib._bootstrap>", line 680, in _load_unlocked
  File "<frozen importlib._bootstrap_external>", line 850, in exec_module
  File "<frozen importlib._bootstrap>", line 228, in _call_with_frames_removed
  File "/data/cailab/flask2024/wsgi.py", line 1, in <module>
    from demo import create_app
  File "/data/cailab/flask2024/demo/__init__.py", line 6, in <module>
    from demo.blueprint.biology import biology
  File "/data/cailab/flask2024/demo/blueprint/biology.py", line 25, in <module>
    from demo.blueprint.modules.core import PipelineForm
  File "/data/cailab/flask2024/demo/blueprint/modules/core.py", line 14, in <module>
    globals()[name+"Form_default"] = getattr(module, name+"Form_default")
AttributeError: module 'demo.blueprint.modules.pipeline_CAPS' has no attribute 'CAPSForm_default'
[2024-06-25 21:28:59 +0800] [372522] [ERROR] Worker (pid:372523) exited with code 3
[2024-06-25 21:28:59 +0800] [372522] [ERROR] Worker (pid:372572) exited with code 3
[2024-06-25 21:35:14 +0800] [373065] [CRITICAL] WORKER TIMEOUT (pid:373067)
[2024-06-25 21:35:14 +0800] [373065] [CRITICAL] WORKER TIMEOUT (pid:373260)
[2024-06-25 21:35:14 +0800] [373067] [ERROR] Error handling request (no URI read)
Traceback (most recent call last):
  File "/data/biosoft/soft2024/conda/anaconda_23.4.7/envs/flask2024/lib/python3.9/site-packages/gunicorn/workers/sync.py", line 134, in handle
    req = next(parser)
  File "/data/biosoft/soft2024/conda/anaconda_23.4.7/envs/flask2024/lib/python3.9/site-packages/gunicorn/http/parser.py", line 42, in __next__
    self.mesg = self.mesg_class(self.cfg, self.unreader, self.source_addr, self.req_count)
  File "/data/biosoft/soft2024/conda/anaconda_23.4.7/envs/flask2024/lib/python3.9/site-packages/gunicorn/http/message.py", line 257, in __init__
    super().__init__(cfg, unreader, peer_addr)
  File "/data/biosoft/soft2024/conda/anaconda_23.4.7/envs/flask2024/lib/python3.9/site-packages/gunicorn/http/message.py", line 60, in __init__
    unused = self.parse(self.unreader)
  File "/data/biosoft/soft2024/conda/anaconda_23.4.7/envs/flask2024/lib/python3.9/site-packages/gunicorn/http/message.py", line 269, in parse
    self.get_data(unreader, buf, stop=True)
  File "/data/biosoft/soft2024/conda/anaconda_23.4.7/envs/flask2024/lib/python3.9/site-packages/gunicorn/http/message.py", line 260, in get_data
    data = unreader.read()
  File "/data/biosoft/soft2024/conda/anaconda_23.4.7/envs/flask2024/lib/python3.9/site-packages/gunicorn/http/unreader.py", line 37, in read
    d = self.chunk()
  File "/data/biosoft/soft2024/conda/anaconda_23.4.7/envs/flask2024/lib/python3.9/site-packages/gunicorn/http/unreader.py", line 64, in chunk
    return self.sock.recv(self.mxchunk)
  File "/data/biosoft/soft2024/conda/anaconda_23.4.7/envs/flask2024/lib/python3.9/site-packages/gunicorn/workers/base.py", line 203, in handle_abort
    sys.exit(1)
SystemExit: 1
[2024-06-25 21:35:14 +0800] [373260] [ERROR] Error handling request (no URI read)
Traceback (most recent call last):
  File "/data/biosoft/soft2024/conda/anaconda_23.4.7/envs/flask2024/lib/python3.9/site-packages/gunicorn/workers/sync.py", line 134, in handle
    req = next(parser)
  File "/data/biosoft/soft2024/conda/anaconda_23.4.7/envs/flask2024/lib/python3.9/site-packages/gunicorn/http/parser.py", line 42, in __next__
    self.mesg = self.mesg_class(self.cfg, self.unreader, self.source_addr, self.req_count)
  File "/data/biosoft/soft2024/conda/anaconda_23.4.7/envs/flask2024/lib/python3.9/site-packages/gunicorn/http/message.py", line 257, in __init__
    super().__init__(cfg, unreader, peer_addr)
  File "/data/biosoft/soft2024/conda/anaconda_23.4.7/envs/flask2024/lib/python3.9/site-packages/gunicorn/http/message.py", line 60, in __init__
    unused = self.parse(self.unreader)
  File "/data/biosoft/soft2024/conda/anaconda_23.4.7/envs/flask2024/lib/python3.9/site-packages/gunicorn/http/message.py", line 269, in parse
    self.get_data(unreader, buf, stop=True)
  File "/data/biosoft/soft2024/conda/anaconda_23.4.7/envs/flask2024/lib/python3.9/site-packages/gunicorn/http/message.py", line 260, in get_data
    data = unreader.read()
  File "/data/biosoft/soft2024/conda/anaconda_23.4.7/envs/flask2024/lib/python3.9/site-packages/gunicorn/http/unreader.py", line 37, in read
    d = self.chunk()
  File "/data/biosoft/soft2024/conda/anaconda_23.4.7/envs/flask2024/lib/python3.9/site-packages/gunicorn/http/unreader.py", line 64, in chunk
    return self.sock.recv(self.mxchunk)
  File "/data/biosoft/soft2024/conda/anaconda_23.4.7/envs/flask2024/lib/python3.9/site-packages/gunicorn/workers/base.py", line 203, in handle_abort
    sys.exit(1)
SystemExit: 1
[2024-06-25 21:35:14 +0800] [373065] [ERROR] Worker (pid:373260) was sent SIGKILL! Perhaps out of memory?
[2024-06-25 21:37:47 +0800] [373065] [CRITICAL] WORKER TIMEOUT (pid:373066)
[2024-06-25 21:37:47 +0800] [373066] [ERROR] Error handling request (no URI read)
Traceback (most recent call last):
  File "/data/biosoft/soft2024/conda/anaconda_23.4.7/envs/flask2024/lib/python3.9/site-packages/gunicorn/workers/sync.py", line 134, in handle
    req = next(parser)
  File "/data/biosoft/soft2024/conda/anaconda_23.4.7/envs/flask2024/lib/python3.9/site-packages/gunicorn/http/parser.py", line 42, in __next__
    self.mesg = self.mesg_class(self.cfg, self.unreader, self.source_addr, self.req_count)
  File "/data/biosoft/soft2024/conda/anaconda_23.4.7/envs/flask2024/lib/python3.9/site-packages/gunicorn/http/message.py", line 257, in __init__
    super().__init__(cfg, unreader, peer_addr)
  File "/data/biosoft/soft2024/conda/anaconda_23.4.7/envs/flask2024/lib/python3.9/site-packages/gunicorn/http/message.py", line 60, in __init__
    unused = self.parse(self.unreader)
  File "/data/biosoft/soft2024/conda/anaconda_23.4.7/envs/flask2024/lib/python3.9/site-packages/gunicorn/http/message.py", line 269, in parse
    self.get_data(unreader, buf, stop=True)
  File "/data/biosoft/soft2024/conda/anaconda_23.4.7/envs/flask2024/lib/python3.9/site-packages/gunicorn/http/message.py", line 260, in get_data
    data = unreader.read()
  File "/data/biosoft/soft2024/conda/anaconda_23.4.7/envs/flask2024/lib/python3.9/site-packages/gunicorn/http/unreader.py", line 37, in read
    d = self.chunk()
  File "/data/biosoft/soft2024/conda/anaconda_23.4.7/envs/flask2024/lib/python3.9/site-packages/gunicorn/http/unreader.py", line 64, in chunk
    return self.sock.recv(self.mxchunk)
  File "/data/biosoft/soft2024/conda/anaconda_23.4.7/envs/flask2024/lib/python3.9/site-packages/gunicorn/workers/base.py", line 203, in handle_abort
    sys.exit(1)
SystemExit: 1
[2024-06-25 21:38:00 +0800] [373069] [ERROR] Error handling request (no URI read)
Traceback (most recent call last):
  File "/data/biosoft/soft2024/conda/anaconda_23.4.7/envs/flask2024/lib/python3.9/site-packages/gunicorn/workers/sync.py", line 134, in handle
    req = next(parser)
  File "/data/biosoft/soft2024/conda/anaconda_23.4.7/envs/flask2024/lib/python3.9/site-packages/gunicorn/http/parser.py", line 42, in __next__
    self.mesg = self.mesg_class(self.cfg, self.unreader, self.source_addr, self.req_count)
  File "/data/biosoft/soft2024/conda/anaconda_23.4.7/envs/flask2024/lib/python3.9/site-packages/gunicorn/http/message.py", line 257, in __init__
    super().__init__(cfg, unreader, peer_addr)
  File "/data/biosoft/soft2024/conda/anaconda_23.4.7/envs/flask2024/lib/python3.9/site-packages/gunicorn/http/message.py", line 60, in __init__
    unused = self.parse(self.unreader)
  File "/data/biosoft/soft2024/conda/anaconda_23.4.7/envs/flask2024/lib/python3.9/site-packages/gunicorn/http/message.py", line 269, in parse
    self.get_data(unreader, buf, stop=True)
  File "/data/biosoft/soft2024/conda/anaconda_23.4.7/envs/flask2024/lib/python3.9/site-packages/gunicorn/http/message.py", line 260, in get_data
    data = unreader.read()
  File "/data/biosoft/soft2024/conda/anaconda_23.4.7/envs/flask2024/lib/python3.9/site-packages/gunicorn/http/unreader.py", line 37, in read
    d = self.chunk()
  File "/data/biosoft/soft2024/conda/anaconda_23.4.7/envs/flask2024/lib/python3.9/site-packages/gunicorn/http/unreader.py", line 64, in chunk
    return self.sock.recv(self.mxchunk)
  File "/data/biosoft/soft2024/conda/anaconda_23.4.7/envs/flask2024/lib/python3.9/site-packages/gunicorn/workers/base.py", line 197, in handle_quit
    time.sleep(0.1)
  File "/data/biosoft/soft2024/conda/anaconda_23.4.7/envs/flask2024/lib/python3.9/site-packages/gunicorn/workers/base.py", line 198, in handle_quit
    sys.exit(0)
SystemExit: 0
[2024-06-25 21:38:00 +0800] [374871] [ERROR] Error handling request (no URI read)
Traceback (most recent call last):
  File "/data/biosoft/soft2024/conda/anaconda_23.4.7/envs/flask2024/lib/python3.9/site-packages/gunicorn/workers/sync.py", line 134, in handle
    req = next(parser)
  File "/data/biosoft/soft2024/conda/anaconda_23.4.7/envs/flask2024/lib/python3.9/site-packages/gunicorn/http/parser.py", line 42, in __next__
    self.mesg = self.mesg_class(self.cfg, self.unreader, self.source_addr, self.req_count)
  File "/data/biosoft/soft2024/conda/anaconda_23.4.7/envs/flask2024/lib/python3.9/site-packages/gunicorn/http/message.py", line 257, in __init__
    super().__init__(cfg, unreader, peer_addr)
  File "/data/biosoft/soft2024/conda/anaconda_23.4.7/envs/flask2024/lib/python3.9/site-packages/gunicorn/http/message.py", line 60, in __init__
    unused = self.parse(self.unreader)
  File "/data/biosoft/soft2024/conda/anaconda_23.4.7/envs/flask2024/lib/python3.9/site-packages/gunicorn/http/message.py", line 269, in parse
    self.get_data(unreader, buf, stop=True)
  File "/data/biosoft/soft2024/conda/anaconda_23.4.7/envs/flask2024/lib/python3.9/site-packages/gunicorn/http/message.py", line 260, in get_data
    data = unreader.read()
  File "/data/biosoft/soft2024/conda/anaconda_23.4.7/envs/flask2024/lib/python3.9/site-packages/gunicorn/http/unreader.py", line 37, in read
    d = self.chunk()
  File "/data/biosoft/soft2024/conda/anaconda_23.4.7/envs/flask2024/lib/python3.9/site-packages/gunicorn/http/unreader.py", line 64, in chunk
    return self.sock.recv(self.mxchunk)
  File "/data/biosoft/soft2024/conda/anaconda_23.4.7/envs/flask2024/lib/python3.9/site-packages/gunicorn/workers/base.py", line 197, in handle_quit
    time.sleep(0.1)
  File "/data/biosoft/soft2024/conda/anaconda_23.4.7/envs/flask2024/lib/python3.9/site-packages/gunicorn/workers/base.py", line 198, in handle_quit
    sys.exit(0)
SystemExit: 0
[2024-06-25 21:53:41,119] ERROR in app: Exception on /check/20240625213811-df5e5b0a-debe-4805-a9f2-e80157653e60 [GET]
Traceback (most recent call last):
  File "/data/biosoft/soft2024/conda/anaconda_23.4.7/envs/flask2024/lib/python3.9/site-packages/flask/app.py", line 1473, in wsgi_app
    response = self.full_dispatch_request()
  File "/data/biosoft/soft2024/conda/anaconda_23.4.7/envs/flask2024/lib/python3.9/site-packages/flask/app.py", line 882, in full_dispatch_request
    rv = self.handle_user_exception(e)
  File "/data/biosoft/soft2024/conda/anaconda_23.4.7/envs/flask2024/lib/python3.9/site-packages/flask/app.py", line 880, in full_dispatch_request
    rv = self.dispatch_request()
  File "/data/biosoft/soft2024/conda/anaconda_23.4.7/envs/flask2024/lib/python3.9/site-packages/flask/app.py", line 865, in dispatch_request
    return self.ensure_sync(self.view_functions[rule.endpoint])(**view_args)  # type: ignore[no-any-return]
  File "/data/cailab/flask2024/demo/blueprint/biology.py", line 61, in check
    fastqs = get_fq_list(selected_folder, info["mode"] != "single")
KeyError: 'mode'
[2024-06-25 22:40:30 +0800] [386795] [ERROR] Worker (pid:386796) was sent SIGHUP!
[2024-06-25 22:40:30 +0800] [386795] [ERROR] Worker (pid:386797) was sent SIGHUP!
[2024-06-25 22:40:30 +0800] [386795] [ERROR] Worker (pid:386798) was sent SIGHUP!
[2024-06-25 22:40:30 +0800] [386795] [ERROR] Worker (pid:386894) was sent SIGHUP!
[2024-06-25 22:40:30 +0800] [386795] [ERROR] Worker (pid:386846) was sent SIGHUP!
[2024-06-25 22:40:30 +0800] [386795] [ERROR] Worker (pid:386942) was sent SIGHUP!
[2024-06-25 22:40:30 +0800] [386795] [ERROR] Worker (pid:386943) was sent SIGHUP!
[2024-06-25 22:40:30 +0800] [386795] [ERROR] Worker (pid:386991) was sent SIGHUP!
[2024-06-25 22:40:30 +0800] [386795] [ERROR] Worker (pid:393455) was sent SIGTERM!
[2024-06-25 22:40:30 +0800] [386795] [ERROR] Worker (pid:393450) was sent SIGTERM!
[2024-06-25 22:40:30 +0800] [386795] [ERROR] Worker (pid:393451) was sent SIGTERM!
[2024-06-25 22:40:30 +0800] [386795] [ERROR] Worker (pid:393454) was sent SIGTERM!
[2024-06-25 22:40:30 +0800] [386795] [ERROR] Worker (pid:393456) was sent SIGTERM!
[2024-06-25 22:40:30 +0800] [386795] [ERROR] Worker (pid:393453) was sent SIGTERM!
[2024-06-25 22:40:30 +0800] [386795] [ERROR] Worker (pid:393449) was sent SIGTERM!
