[2024-05-30 13:53:39 +0800] [64570] [ERROR] Worker (pid:64578) was sent SIGHUP!
[2024-05-30 13:53:39 +0800] [64570] [ERROR] Worker (pid:64577) was sent SIGHUP!
[2024-05-30 13:53:39 +0800] [64570] [ERROR] Worker (pid:64574) was sent SIGHUP!
[2024-05-30 13:53:39 +0800] [64570] [ERROR] Worker (pid:64580) was sent SIGHUP!
[2024-05-30 13:53:39 +0800] [64570] [ERROR] Worker (pid:64579) was sent SIGHUP!
[2024-05-30 13:53:39 +0800] [64570] [ERROR] Worker (pid:64576) was sent SIGHUP!
[2024-05-30 13:53:39 +0800] [64570] [ERROR] Worker (pid:64573) was sent SIGHUP!
[2024-05-30 13:53:39 +0800] [64570] [ERROR] Worker (pid:64575) was sent SIGHUP!
[2024-05-30 13:53:40 +0800] [64570] [ERROR] Worker (pid:73149) was sent SIGTERM!
[2024-05-30 13:53:40 +0800] [64570] [ERROR] Worker (pid:73155) was sent SIGTERM!
[2024-05-30 13:53:40 +0800] [64570] [ERROR] Worker (pid:73154) was sent SIGTERM!
[2024-05-30 13:53:40 +0800] [64570] [ERROR] Worker (pid:73152) was sent SIGTERM!
[2024-05-30 13:53:40 +0800] [64570] [ERROR] Worker (pid:73151) was sent SIGTERM!
[2024-06-04 14:03:20 +0800] [314926] [ERROR] Exception in worker process
Traceback (most recent call last):
  File "/data/biosoft/soft2024/conda/anaconda_23.4.7/envs/flask2024/lib/python3.9/site-packages/gunicorn/arbiter.py", line 609, in spawn_worker
    worker.init_process()
  File "/data/biosoft/soft2024/conda/anaconda_23.4.7/envs/flask2024/lib/python3.9/site-packages/gunicorn/workers/base.py", line 134, in init_process
    self.load_wsgi()
  File "/data/biosoft/soft2024/conda/anaconda_23.4.7/envs/flask2024/lib/python3.9/site-packages/gunicorn/workers/base.py", line 146, in load_wsgi
    self.wsgi = self.app.wsgi()
  File "/data/biosoft/soft2024/conda/anaconda_23.4.7/envs/flask2024/lib/python3.9/site-packages/gunicorn/app/base.py", line 67, in wsgi
    self.callable = self.load()
  File "/data/biosoft/soft2024/conda/anaconda_23.4.7/envs/flask2024/lib/python3.9/site-packages/gunicorn/app/wsgiapp.py", line 58, in load
    return self.load_wsgiapp()
  File "/data/biosoft/soft2024/conda/anaconda_23.4.7/envs/flask2024/lib/python3.9/site-packages/gunicorn/app/wsgiapp.py", line 48, in load_wsgiapp
    return util.import_app(self.app_uri)
  File "/data/biosoft/soft2024/conda/anaconda_23.4.7/envs/flask2024/lib/python3.9/site-packages/gunicorn/util.py", line 371, in import_app
    mod = importlib.import_module(module)
  File "/data/biosoft/soft2024/conda/anaconda_23.4.7/envs/flask2024/lib/python3.9/importlib/__init__.py", line 127, in import_module
    return _bootstrap._gcd_import(name[level:], package, level)
  File "<frozen importlib._bootstrap>", line 1030, in _gcd_import
  File "<frozen importlib._bootstrap>", line 1007, in _find_and_load
  File "<frozen importlib._bootstrap>", line 986, in _find_and_load_unlocked
  File "<frozen importlib._bootstrap>", line 680, in _load_unlocked
  File "<frozen importlib._bootstrap_external>", line 850, in exec_module
  File "<frozen importlib._bootstrap>", line 228, in _call_with_frames_removed
  File "/data/cailab/flask2024/wsgi.py", line 2, in <module>
    app = create_app()
  File "/data/cailab/flask2024/demo/__init__.py", line 23, in create_app
    app.register_blueprint(analysis_bp)
  File "/data/biosoft/soft2024/conda/anaconda_23.4.7/envs/flask2024/lib/python3.9/site-packages/flask/sansio/scaffold.py", line 47, in wrapper_func
    return f(self, *args, **kwargs)
  File "/data/biosoft/soft2024/conda/anaconda_23.4.7/envs/flask2024/lib/python3.9/site-packages/flask/sansio/app.py", line 595, in register_blueprint
    blueprint.register(self, options)
  File "/data/biosoft/soft2024/conda/anaconda_23.4.7/envs/flask2024/lib/python3.9/site-packages/flask/sansio/blueprints.py", line 310, in register
    raise ValueError(
ValueError: The name 'analysis' is already registered for a different blueprint. Use 'name=' to provide a unique name.
[2024-06-04 14:03:20 +0800] [314925] [ERROR] Exception in worker process
Traceback (most recent call last):
  File "/data/biosoft/soft2024/conda/anaconda_23.4.7/envs/flask2024/lib/python3.9/site-packages/gunicorn/arbiter.py", line 609, in spawn_worker
    worker.init_process()
  File "/data/biosoft/soft2024/conda/anaconda_23.4.7/envs/flask2024/lib/python3.9/site-packages/gunicorn/workers/base.py", line 134, in init_process
    self.load_wsgi()
  File "/data/biosoft/soft2024/conda/anaconda_23.4.7/envs/flask2024/lib/python3.9/site-packages/gunicorn/workers/base.py", line 146, in load_wsgi
    self.wsgi = self.app.wsgi()
  File "/data/biosoft/soft2024/conda/anaconda_23.4.7/envs/flask2024/lib/python3.9/site-packages/gunicorn/app/base.py", line 67, in wsgi
    self.callable = self.load()
  File "/data/biosoft/soft2024/conda/anaconda_23.4.7/envs/flask2024/lib/python3.9/site-packages/gunicorn/app/wsgiapp.py", line 58, in load
    return self.load_wsgiapp()
  File "/data/biosoft/soft2024/conda/anaconda_23.4.7/envs/flask2024/lib/python3.9/site-packages/gunicorn/app/wsgiapp.py", line 48, in load_wsgiapp
    return util.import_app(self.app_uri)
  File "/data/biosoft/soft2024/conda/anaconda_23.4.7/envs/flask2024/lib/python3.9/site-packages/gunicorn/util.py", line 371, in import_app
    mod = importlib.import_module(module)
  File "/data/biosoft/soft2024/conda/anaconda_23.4.7/envs/flask2024/lib/python3.9/importlib/__init__.py", line 127, in import_module
    return _bootstrap._gcd_import(name[level:], package, level)
  File "<frozen importlib._bootstrap>", line 1030, in _gcd_import
  File "<frozen importlib._bootstrap>", line 1007, in _find_and_load
  File "<frozen importlib._bootstrap>", line 986, in _find_and_load_unlocked
  File "<frozen importlib._bootstrap>", line 680, in _load_unlocked
  File "<frozen importlib._bootstrap_external>", line 850, in exec_module
  File "<frozen importlib._bootstrap>", line 228, in _call_with_frames_removed
  File "/data/cailab/flask2024/wsgi.py", line 2, in <module>
    app = create_app()
  File "/data/cailab/flask2024/demo/__init__.py", line 23, in create_app
    app.register_blueprint(analysis_bp)
  File "/data/biosoft/soft2024/conda/anaconda_23.4.7/envs/flask2024/lib/python3.9/site-packages/flask/sansio/scaffold.py", line 47, in wrapper_func
    return f(self, *args, **kwargs)
  File "/data/biosoft/soft2024/conda/anaconda_23.4.7/envs/flask2024/lib/python3.9/site-packages/flask/sansio/app.py", line 595, in register_blueprint
    blueprint.register(self, options)
  File "/data/biosoft/soft2024/conda/anaconda_23.4.7/envs/flask2024/lib/python3.9/site-packages/flask/sansio/blueprints.py", line 310, in register
    raise ValueError(
ValueError: The name 'analysis' is already registered for a different blueprint. Use 'name=' to provide a unique name.
[2024-06-04 14:03:20 +0800] [315048] [ERROR] Exception in worker process
Traceback (most recent call last):
  File "/data/biosoft/soft2024/conda/anaconda_23.4.7/envs/flask2024/lib/python3.9/site-packages/gunicorn/arbiter.py", line 609, in spawn_worker
    worker.init_process()
  File "/data/biosoft/soft2024/conda/anaconda_23.4.7/envs/flask2024/lib/python3.9/site-packages/gunicorn/workers/base.py", line 134, in init_process
    self.load_wsgi()
  File "/data/biosoft/soft2024/conda/anaconda_23.4.7/envs/flask2024/lib/python3.9/site-packages/gunicorn/workers/base.py", line 146, in load_wsgi
    self.wsgi = self.app.wsgi()
  File "/data/biosoft/soft2024/conda/anaconda_23.4.7/envs/flask2024/lib/python3.9/site-packages/gunicorn/app/base.py", line 67, in wsgi
    self.callable = self.load()
  File "/data/biosoft/soft2024/conda/anaconda_23.4.7/envs/flask2024/lib/python3.9/site-packages/gunicorn/app/wsgiapp.py", line 58, in load
    return self.load_wsgiapp()
  File "/data/biosoft/soft2024/conda/anaconda_23.4.7/envs/flask2024/lib/python3.9/site-packages/gunicorn/app/wsgiapp.py", line 48, in load_wsgiapp
    return util.import_app(self.app_uri)
  File "/data/biosoft/soft2024/conda/anaconda_23.4.7/envs/flask2024/lib/python3.9/site-packages/gunicorn/util.py", line 371, in import_app
    mod = importlib.import_module(module)
  File "/data/biosoft/soft2024/conda/anaconda_23.4.7/envs/flask2024/lib/python3.9/importlib/__init__.py", line 127, in import_module
    return _bootstrap._gcd_import(name[level:], package, level)
  File "<frozen importlib._bootstrap>", line 1030, in _gcd_import
  File "<frozen importlib._bootstrap>", line 1007, in _find_and_load
  File "<frozen importlib._bootstrap>", line 986, in _find_and_load_unlocked
  File "<frozen importlib._bootstrap>", line 680, in _load_unlocked
  File "<frozen importlib._bootstrap_external>", line 850, in exec_module
  File "<frozen importlib._bootstrap>", line 228, in _call_with_frames_removed
  File "/data/cailab/flask2024/wsgi.py", line 2, in <module>
    app = create_app()
  File "/data/cailab/flask2024/demo/__init__.py", line 23, in create_app
    app.register_blueprint(analysis_bp)
  File "/data/biosoft/soft2024/conda/anaconda_23.4.7/envs/flask2024/lib/python3.9/site-packages/flask/sansio/scaffold.py", line 47, in wrapper_func
    return f(self, *args, **kwargs)
  File "/data/biosoft/soft2024/conda/anaconda_23.4.7/envs/flask2024/lib/python3.9/site-packages/flask/sansio/app.py", line 595, in register_blueprint
    blueprint.register(self, options)
  File "/data/biosoft/soft2024/conda/anaconda_23.4.7/envs/flask2024/lib/python3.9/site-packages/flask/sansio/blueprints.py", line 310, in register
    raise ValueError(
ValueError: The name 'analysis' is already registered for a different blueprint. Use 'name=' to provide a unique name.
[2024-06-04 14:03:20 +0800] [314924] [ERROR] Exception in worker process
Traceback (most recent call last):
  File "/data/biosoft/soft2024/conda/anaconda_23.4.7/envs/flask2024/lib/python3.9/site-packages/gunicorn/arbiter.py", line 609, in spawn_worker
    worker.init_process()
  File "/data/biosoft/soft2024/conda/anaconda_23.4.7/envs/flask2024/lib/python3.9/site-packages/gunicorn/workers/base.py", line 134, in init_process
    self.load_wsgi()
  File "/data/biosoft/soft2024/conda/anaconda_23.4.7/envs/flask2024/lib/python3.9/site-packages/gunicorn/workers/base.py", line 146, in load_wsgi
    self.wsgi = self.app.wsgi()
  File "/data/biosoft/soft2024/conda/anaconda_23.4.7/envs/flask2024/lib/python3.9/site-packages/gunicorn/app/base.py", line 67, in wsgi
    self.callable = self.load()
  File "/data/biosoft/soft2024/conda/anaconda_23.4.7/envs/flask2024/lib/python3.9/site-packages/gunicorn/app/wsgiapp.py", line 58, in load
    return self.load_wsgiapp()
  File "/data/biosoft/soft2024/conda/anaconda_23.4.7/envs/flask2024/lib/python3.9/site-packages/gunicorn/app/wsgiapp.py", line 48, in load_wsgiapp
    return util.import_app(self.app_uri)
  File "/data/biosoft/soft2024/conda/anaconda_23.4.7/envs/flask2024/lib/python3.9/site-packages/gunicorn/util.py", line 371, in import_app
    mod = importlib.import_module(module)
  File "/data/biosoft/soft2024/conda/anaconda_23.4.7/envs/flask2024/lib/python3.9/importlib/__init__.py", line 127, in import_module
    return _bootstrap._gcd_import(name[level:], package, level)
  File "<frozen importlib._bootstrap>", line 1030, in _gcd_import
  File "<frozen importlib._bootstrap>", line 1007, in _find_and_load
  File "<frozen importlib._bootstrap>", line 986, in _find_and_load_unlocked
  File "<frozen importlib._bootstrap>", line 680, in _load_unlocked
  File "<frozen importlib._bootstrap_external>", line 850, in exec_module
  File "<frozen importlib._bootstrap>", line 228, in _call_with_frames_removed
  File "/data/cailab/flask2024/wsgi.py", line 2, in <module>
    app = create_app()
  File "/data/cailab/flask2024/demo/__init__.py", line 23, in create_app
    app.register_blueprint(analysis_bp)
  File "/data/biosoft/soft2024/conda/anaconda_23.4.7/envs/flask2024/lib/python3.9/site-packages/flask/sansio/scaffold.py", line 47, in wrapper_func
    return f(self, *args, **kwargs)
  File "/data/biosoft/soft2024/conda/anaconda_23.4.7/envs/flask2024/lib/python3.9/site-packages/flask/sansio/app.py", line 595, in register_blueprint
    blueprint.register(self, options)
  File "/data/biosoft/soft2024/conda/anaconda_23.4.7/envs/flask2024/lib/python3.9/site-packages/flask/sansio/blueprints.py", line 310, in register
    raise ValueError(
ValueError: The name 'analysis' is already registered for a different blueprint. Use 'name=' to provide a unique name.
[2024-06-04 14:03:20 +0800] [314923] [ERROR] Exception in worker process
Traceback (most recent call last):
  File "/data/biosoft/soft2024/conda/anaconda_23.4.7/envs/flask2024/lib/python3.9/site-packages/gunicorn/arbiter.py", line 609, in spawn_worker
    worker.init_process()
  File "/data/biosoft/soft2024/conda/anaconda_23.4.7/envs/flask2024/lib/python3.9/site-packages/gunicorn/workers/base.py", line 134, in init_process
    self.load_wsgi()
  File "/data/biosoft/soft2024/conda/anaconda_23.4.7/envs/flask2024/lib/python3.9/site-packages/gunicorn/workers/base.py", line 146, in load_wsgi
    self.wsgi = self.app.wsgi()
  File "/data/biosoft/soft2024/conda/anaconda_23.4.7/envs/flask2024/lib/python3.9/site-packages/gunicorn/app/base.py", line 67, in wsgi
    self.callable = self.load()
  File "/data/biosoft/soft2024/conda/anaconda_23.4.7/envs/flask2024/lib/python3.9/site-packages/gunicorn/app/wsgiapp.py", line 58, in load
    return self.load_wsgiapp()
  File "/data/biosoft/soft2024/conda/anaconda_23.4.7/envs/flask2024/lib/python3.9/site-packages/gunicorn/app/wsgiapp.py", line 48, in load_wsgiapp
    return util.import_app(self.app_uri)
  File "/data/biosoft/soft2024/conda/anaconda_23.4.7/envs/flask2024/lib/python3.9/site-packages/gunicorn/util.py", line 371, in import_app
    mod = importlib.import_module(module)
  File "/data/biosoft/soft2024/conda/anaconda_23.4.7/envs/flask2024/lib/python3.9/importlib/__init__.py", line 127, in import_module
    return _bootstrap._gcd_import(name[level:], package, level)
  File "<frozen importlib._bootstrap>", line 1030, in _gcd_import
  File "<frozen importlib._bootstrap>", line 1007, in _find_and_load
  File "<frozen importlib._bootstrap>", line 986, in _find_and_load_unlocked
  File "<frozen importlib._bootstrap>", line 680, in _load_unlocked
  File "<frozen importlib._bootstrap_external>", line 850, in exec_module
  File "<frozen importlib._bootstrap>", line 228, in _call_with_frames_removed
  File "/data/cailab/flask2024/wsgi.py", line 2, in <module>
    app = create_app()
  File "/data/cailab/flask2024/demo/__init__.py", line 23, in create_app
    app.register_blueprint(analysis_bp)
  File "/data/biosoft/soft2024/conda/anaconda_23.4.7/envs/flask2024/lib/python3.9/site-packages/flask/sansio/scaffold.py", line 47, in wrapper_func
    return f(self, *args, **kwargs)
  File "/data/biosoft/soft2024/conda/anaconda_23.4.7/envs/flask2024/lib/python3.9/site-packages/flask/sansio/app.py", line 595, in register_blueprint
    blueprint.register(self, options)
  File "/data/biosoft/soft2024/conda/anaconda_23.4.7/envs/flask2024/lib/python3.9/site-packages/flask/sansio/blueprints.py", line 310, in register
    raise ValueError(
ValueError: The name 'analysis' is already registered for a different blueprint. Use 'name=' to provide a unique name.
[2024-06-04 14:03:20 +0800] [314922] [ERROR] Exception in worker process
Traceback (most recent call last):
  File "/data/biosoft/soft2024/conda/anaconda_23.4.7/envs/flask2024/lib/python3.9/site-packages/gunicorn/arbiter.py", line 609, in spawn_worker
    worker.init_process()
  File "/data/biosoft/soft2024/conda/anaconda_23.4.7/envs/flask2024/lib/python3.9/site-packages/gunicorn/workers/base.py", line 134, in init_process
    self.load_wsgi()
  File "/data/biosoft/soft2024/conda/anaconda_23.4.7/envs/flask2024/lib/python3.9/site-packages/gunicorn/workers/base.py", line 146, in load_wsgi
    self.wsgi = self.app.wsgi()
  File "/data/biosoft/soft2024/conda/anaconda_23.4.7/envs/flask2024/lib/python3.9/site-packages/gunicorn/app/base.py", line 67, in wsgi
    self.callable = self.load()
  File "/data/biosoft/soft2024/conda/anaconda_23.4.7/envs/flask2024/lib/python3.9/site-packages/gunicorn/app/wsgiapp.py", line 58, in load
    return self.load_wsgiapp()
  File "/data/biosoft/soft2024/conda/anaconda_23.4.7/envs/flask2024/lib/python3.9/site-packages/gunicorn/app/wsgiapp.py", line 48, in load_wsgiapp
    return util.import_app(self.app_uri)
  File "/data/biosoft/soft2024/conda/anaconda_23.4.7/envs/flask2024/lib/python3.9/site-packages/gunicorn/util.py", line 371, in import_app
    mod = importlib.import_module(module)
  File "/data/biosoft/soft2024/conda/anaconda_23.4.7/envs/flask2024/lib/python3.9/importlib/__init__.py", line 127, in import_module
    return _bootstrap._gcd_import(name[level:], package, level)
  File "<frozen importlib._bootstrap>", line 1030, in _gcd_import
  File "<frozen importlib._bootstrap>", line 1007, in _find_and_load
  File "<frozen importlib._bootstrap>", line 986, in _find_and_load_unlocked
  File "<frozen importlib._bootstrap>", line 680, in _load_unlocked
  File "<frozen importlib._bootstrap_external>", line 850, in exec_module
  File "<frozen importlib._bootstrap>", line 228, in _call_with_frames_removed
  File "/data/cailab/flask2024/wsgi.py", line 2, in <module>
    app = create_app()
  File "/data/cailab/flask2024/demo/__init__.py", line 23, in create_app
    app.register_blueprint(analysis_bp)
  File "/data/biosoft/soft2024/conda/anaconda_23.4.7/envs/flask2024/lib/python3.9/site-packages/flask/sansio/scaffold.py", line 47, in wrapper_func
    return f(self, *args, **kwargs)
  File "/data/biosoft/soft2024/conda/anaconda_23.4.7/envs/flask2024/lib/python3.9/site-packages/flask/sansio/app.py", line 595, in register_blueprint
    blueprint.register(self, options)
  File "/data/biosoft/soft2024/conda/anaconda_23.4.7/envs/flask2024/lib/python3.9/site-packages/flask/sansio/blueprints.py", line 310, in register
    raise ValueError(
ValueError: The name 'analysis' is already registered for a different blueprint. Use 'name=' to provide a unique name.
[2024-06-04 14:03:20 +0800] [315116] [ERROR] Exception in worker process
Traceback (most recent call last):
  File "/data/biosoft/soft2024/conda/anaconda_23.4.7/envs/flask2024/lib/python3.9/site-packages/gunicorn/arbiter.py", line 609, in spawn_worker
    worker.init_process()
  File "/data/biosoft/soft2024/conda/anaconda_23.4.7/envs/flask2024/lib/python3.9/site-packages/gunicorn/workers/base.py", line 134, in init_process
    self.load_wsgi()
  File "/data/biosoft/soft2024/conda/anaconda_23.4.7/envs/flask2024/lib/python3.9/site-packages/gunicorn/workers/base.py", line 146, in load_wsgi
    self.wsgi = self.app.wsgi()
  File "/data/biosoft/soft2024/conda/anaconda_23.4.7/envs/flask2024/lib/python3.9/site-packages/gunicorn/app/base.py", line 67, in wsgi
    self.callable = self.load()
  File "/data/biosoft/soft2024/conda/anaconda_23.4.7/envs/flask2024/lib/python3.9/site-packages/gunicorn/app/wsgiapp.py", line 58, in load
    return self.load_wsgiapp()
  File "/data/biosoft/soft2024/conda/anaconda_23.4.7/envs/flask2024/lib/python3.9/site-packages/gunicorn/app/wsgiapp.py", line 48, in load_wsgiapp
    return util.import_app(self.app_uri)
  File "/data/biosoft/soft2024/conda/anaconda_23.4.7/envs/flask2024/lib/python3.9/site-packages/gunicorn/util.py", line 371, in import_app
    mod = importlib.import_module(module)
  File "/data/biosoft/soft2024/conda/anaconda_23.4.7/envs/flask2024/lib/python3.9/importlib/__init__.py", line 127, in import_module
    return _bootstrap._gcd_import(name[level:], package, level)
  File "<frozen importlib._bootstrap>", line 1030, in _gcd_import
  File "<frozen importlib._bootstrap>", line 1007, in _find_and_load
  File "<frozen importlib._bootstrap>", line 986, in _find_and_load_unlocked
  File "<frozen importlib._bootstrap>", line 680, in _load_unlocked
  File "<frozen importlib._bootstrap_external>", line 850, in exec_module
  File "<frozen importlib._bootstrap>", line 228, in _call_with_frames_removed
  File "/data/cailab/flask2024/wsgi.py", line 2, in <module>
    app = create_app()
  File "/data/cailab/flask2024/demo/__init__.py", line 23, in create_app
    app.register_blueprint(analysis_bp)
  File "/data/biosoft/soft2024/conda/anaconda_23.4.7/envs/flask2024/lib/python3.9/site-packages/flask/sansio/scaffold.py", line 47, in wrapper_func
    return f(self, *args, **kwargs)
  File "/data/biosoft/soft2024/conda/anaconda_23.4.7/envs/flask2024/lib/python3.9/site-packages/flask/sansio/app.py", line 595, in register_blueprint
    blueprint.register(self, options)
  File "/data/biosoft/soft2024/conda/anaconda_23.4.7/envs/flask2024/lib/python3.9/site-packages/flask/sansio/blueprints.py", line 310, in register
    raise ValueError(
ValueError: The name 'analysis' is already registered for a different blueprint. Use 'name=' to provide a unique name.
[2024-06-04 14:03:20 +0800] [315117] [ERROR] Exception in worker process
Traceback (most recent call last):
  File "/data/biosoft/soft2024/conda/anaconda_23.4.7/envs/flask2024/lib/python3.9/site-packages/gunicorn/arbiter.py", line 609, in spawn_worker
    worker.init_process()
  File "/data/biosoft/soft2024/conda/anaconda_23.4.7/envs/flask2024/lib/python3.9/site-packages/gunicorn/workers/base.py", line 134, in init_process
    self.load_wsgi()
  File "/data/biosoft/soft2024/conda/anaconda_23.4.7/envs/flask2024/lib/python3.9/site-packages/gunicorn/workers/base.py", line 146, in load_wsgi
    self.wsgi = self.app.wsgi()
  File "/data/biosoft/soft2024/conda/anaconda_23.4.7/envs/flask2024/lib/python3.9/site-packages/gunicorn/app/base.py", line 67, in wsgi
    self.callable = self.load()
  File "/data/biosoft/soft2024/conda/anaconda_23.4.7/envs/flask2024/lib/python3.9/site-packages/gunicorn/app/wsgiapp.py", line 58, in load
    return self.load_wsgiapp()
  File "/data/biosoft/soft2024/conda/anaconda_23.4.7/envs/flask2024/lib/python3.9/site-packages/gunicorn/app/wsgiapp.py", line 48, in load_wsgiapp
    return util.import_app(self.app_uri)
  File "/data/biosoft/soft2024/conda/anaconda_23.4.7/envs/flask2024/lib/python3.9/site-packages/gunicorn/util.py", line 371, in import_app
    mod = importlib.import_module(module)
  File "/data/biosoft/soft2024/conda/anaconda_23.4.7/envs/flask2024/lib/python3.9/importlib/__init__.py", line 127, in import_module
    return _bootstrap._gcd_import(name[level:], package, level)
  File "<frozen importlib._bootstrap>", line 1030, in _gcd_import
  File "<frozen importlib._bootstrap>", line 1007, in _find_and_load
  File "<frozen importlib._bootstrap>", line 986, in _find_and_load_unlocked
  File "<frozen importlib._bootstrap>", line 680, in _load_unlocked
  File "<frozen importlib._bootstrap_external>", line 850, in exec_module
  File "<frozen importlib._bootstrap>", line 228, in _call_with_frames_removed
  File "/data/cailab/flask2024/wsgi.py", line 2, in <module>
    app = create_app()
  File "/data/cailab/flask2024/demo/__init__.py", line 23, in create_app
    app.register_blueprint(analysis_bp)
  File "/data/biosoft/soft2024/conda/anaconda_23.4.7/envs/flask2024/lib/python3.9/site-packages/flask/sansio/scaffold.py", line 47, in wrapper_func
    return f(self, *args, **kwargs)
  File "/data/biosoft/soft2024/conda/anaconda_23.4.7/envs/flask2024/lib/python3.9/site-packages/flask/sansio/app.py", line 595, in register_blueprint
    blueprint.register(self, options)
  File "/data/biosoft/soft2024/conda/anaconda_23.4.7/envs/flask2024/lib/python3.9/site-packages/flask/sansio/blueprints.py", line 310, in register
    raise ValueError(
ValueError: The name 'analysis' is already registered for a different blueprint. Use 'name=' to provide a unique name.
[2024-06-04 14:03:20 +0800] [314921] [ERROR] Worker (pid:315116) exited with code 3
[2024-06-04 14:03:20 +0800] [314921] [ERROR] Worker (pid:314923) exited with code 3
[2024-06-04 14:04:51 +0800] [315689] [ERROR] Error handling request (no URI read)
Traceback (most recent call last):
  File "/data/biosoft/soft2024/conda/anaconda_23.4.7/envs/flask2024/lib/python3.9/site-packages/gunicorn/workers/sync.py", line 134, in handle
    req = next(parser)
  File "/data/biosoft/soft2024/conda/anaconda_23.4.7/envs/flask2024/lib/python3.9/site-packages/gunicorn/http/parser.py", line 42, in __next__
    self.mesg = self.mesg_class(self.cfg, self.unreader, self.source_addr, self.req_count)
  File "/data/biosoft/soft2024/conda/anaconda_23.4.7/envs/flask2024/lib/python3.9/site-packages/gunicorn/http/message.py", line 257, in __init__
    super().__init__(cfg, unreader, peer_addr)
  File "/data/biosoft/soft2024/conda/anaconda_23.4.7/envs/flask2024/lib/python3.9/site-packages/gunicorn/http/message.py", line 60, in __init__
    unused = self.parse(self.unreader)
  File "/data/biosoft/soft2024/conda/anaconda_23.4.7/envs/flask2024/lib/python3.9/site-packages/gunicorn/http/message.py", line 269, in parse
    self.get_data(unreader, buf, stop=True)
  File "/data/biosoft/soft2024/conda/anaconda_23.4.7/envs/flask2024/lib/python3.9/site-packages/gunicorn/http/message.py", line 260, in get_data
    data = unreader.read()
  File "/data/biosoft/soft2024/conda/anaconda_23.4.7/envs/flask2024/lib/python3.9/site-packages/gunicorn/http/unreader.py", line 37, in read
    d = self.chunk()
  File "/data/biosoft/soft2024/conda/anaconda_23.4.7/envs/flask2024/lib/python3.9/site-packages/gunicorn/http/unreader.py", line 64, in chunk
    return self.sock.recv(self.mxchunk)
  File "/data/biosoft/soft2024/conda/anaconda_23.4.7/envs/flask2024/lib/python3.9/site-packages/gunicorn/workers/base.py", line 197, in handle_quit
    time.sleep(0.1)
  File "/data/biosoft/soft2024/conda/anaconda_23.4.7/envs/flask2024/lib/python3.9/site-packages/gunicorn/workers/base.py", line 198, in handle_quit
    sys.exit(0)
SystemExit: 0
[2024-06-04 14:04:51 +0800] [315544] [ERROR] Error handling request (no URI read)
Traceback (most recent call last):
  File "/data/biosoft/soft2024/conda/anaconda_23.4.7/envs/flask2024/lib/python3.9/site-packages/gunicorn/workers/sync.py", line 134, in handle
    req = next(parser)
  File "/data/biosoft/soft2024/conda/anaconda_23.4.7/envs/flask2024/lib/python3.9/site-packages/gunicorn/http/parser.py", line 42, in __next__
    self.mesg = self.mesg_class(self.cfg, self.unreader, self.source_addr, self.req_count)
  File "/data/biosoft/soft2024/conda/anaconda_23.4.7/envs/flask2024/lib/python3.9/site-packages/gunicorn/http/message.py", line 257, in __init__
    super().__init__(cfg, unreader, peer_addr)
  File "/data/biosoft/soft2024/conda/anaconda_23.4.7/envs/flask2024/lib/python3.9/site-packages/gunicorn/http/message.py", line 60, in __init__
    unused = self.parse(self.unreader)
  File "/data/biosoft/soft2024/conda/anaconda_23.4.7/envs/flask2024/lib/python3.9/site-packages/gunicorn/http/message.py", line 269, in parse
    self.get_data(unreader, buf, stop=True)
  File "/data/biosoft/soft2024/conda/anaconda_23.4.7/envs/flask2024/lib/python3.9/site-packages/gunicorn/http/message.py", line 260, in get_data
    data = unreader.read()
  File "/data/biosoft/soft2024/conda/anaconda_23.4.7/envs/flask2024/lib/python3.9/site-packages/gunicorn/http/unreader.py", line 37, in read
    d = self.chunk()
  File "/data/biosoft/soft2024/conda/anaconda_23.4.7/envs/flask2024/lib/python3.9/site-packages/gunicorn/http/unreader.py", line 64, in chunk
    return self.sock.recv(self.mxchunk)
  File "/data/biosoft/soft2024/conda/anaconda_23.4.7/envs/flask2024/lib/python3.9/site-packages/gunicorn/workers/base.py", line 197, in handle_quit
    time.sleep(0.1)
  File "/data/biosoft/soft2024/conda/anaconda_23.4.7/envs/flask2024/lib/python3.9/site-packages/gunicorn/workers/base.py", line 198, in handle_quit
    sys.exit(0)
SystemExit: 0
[2024-06-04 14:05:08,216] ERROR in app: Exception on /hidden [GET]
Traceback (most recent call last):
  File "/data/biosoft/soft2024/conda/anaconda_23.4.7/envs/flask2024/lib/python3.9/site-packages/flask/app.py", line 1473, in wsgi_app
    response = self.full_dispatch_request()
  File "/data/biosoft/soft2024/conda/anaconda_23.4.7/envs/flask2024/lib/python3.9/site-packages/flask/app.py", line 882, in full_dispatch_request
    rv = self.handle_user_exception(e)
  File "/data/biosoft/soft2024/conda/anaconda_23.4.7/envs/flask2024/lib/python3.9/site-packages/flask/app.py", line 880, in full_dispatch_request
    rv = self.dispatch_request()
  File "/data/biosoft/soft2024/conda/anaconda_23.4.7/envs/flask2024/lib/python3.9/site-packages/flask/app.py", line 865, in dispatch_request
    return self.ensure_sync(self.view_functions[rule.endpoint])(**view_args)  # type: ignore[no-any-return]
  File "/data/cailab/flask2024/demo/blueprint/hidden.py", line 7, in hidden
    return render_template('hidden/home.html')
  File "/data/biosoft/soft2024/conda/anaconda_23.4.7/envs/flask2024/lib/python3.9/site-packages/flask/templating.py", line 150, in render_template
    return _render(app, template, context)
  File "/data/biosoft/soft2024/conda/anaconda_23.4.7/envs/flask2024/lib/python3.9/site-packages/flask/templating.py", line 131, in _render
    rv = template.render(context)
  File "/data/biosoft/soft2024/conda/anaconda_23.4.7/envs/flask2024/lib/python3.9/site-packages/jinja2/environment.py", line 1301, in render
    self.environment.handle_exception()
  File "/data/biosoft/soft2024/conda/anaconda_23.4.7/envs/flask2024/lib/python3.9/site-packages/jinja2/environment.py", line 936, in handle_exception
    raise rewrite_traceback_stack(source=source)
  File "/data/cailab/flask2024/demo/templates/hidden/home.html", line 3, in top-level template code
    {% from 'bootstrap4/form.html' import render_form %}
  File "/data/cailab/flask2024/demo/templates/base.html", line 38, in top-level template code
    {% block content %}
  File "/data/cailab/flask2024/demo/templates/hidden/home.html", line 30, in block 'content'
    {{ render_form(form, extra_classes='col-lg-20') }}
  File "/data/biosoft/soft2024/conda/anaconda_23.4.7/envs/flask2024/lib/python3.9/site-packages/jinja2/runtime.py", line 777, in _invoke
    rv = self._func(*arguments)
  File "/data/biosoft/soft2024/conda/anaconda_23.4.7/envs/flask2024/lib/python3.9/site-packages/flask_bootstrap/templates/bootstrap4/form.html", line 299, in template
    {{ form.hidden_tag() }}
  File "/data/biosoft/soft2024/conda/anaconda_23.4.7/envs/flask2024/lib/python3.9/site-packages/jinja2/environment.py", line 485, in getattr
    return getattr(obj, attribute)
jinja2.exceptions.UndefinedError: 'form' is undefined
[2024-06-04 14:05:39 +0800] [316012] [CRITICAL] WORKER TIMEOUT (pid:316064)
[2024-06-04 14:05:39 +0800] [316064] [ERROR] Error handling request (no URI read)
Traceback (most recent call last):
  File "/data/biosoft/soft2024/conda/anaconda_23.4.7/envs/flask2024/lib/python3.9/site-packages/gunicorn/workers/sync.py", line 134, in handle
    req = next(parser)
  File "/data/biosoft/soft2024/conda/anaconda_23.4.7/envs/flask2024/lib/python3.9/site-packages/gunicorn/http/parser.py", line 42, in __next__
    self.mesg = self.mesg_class(self.cfg, self.unreader, self.source_addr, self.req_count)
  File "/data/biosoft/soft2024/conda/anaconda_23.4.7/envs/flask2024/lib/python3.9/site-packages/gunicorn/http/message.py", line 257, in __init__
    super().__init__(cfg, unreader, peer_addr)
  File "/data/biosoft/soft2024/conda/anaconda_23.4.7/envs/flask2024/lib/python3.9/site-packages/gunicorn/http/message.py", line 60, in __init__
    unused = self.parse(self.unreader)
  File "/data/biosoft/soft2024/conda/anaconda_23.4.7/envs/flask2024/lib/python3.9/site-packages/gunicorn/http/message.py", line 269, in parse
    self.get_data(unreader, buf, stop=True)
  File "/data/biosoft/soft2024/conda/anaconda_23.4.7/envs/flask2024/lib/python3.9/site-packages/gunicorn/http/message.py", line 260, in get_data
    data = unreader.read()
  File "/data/biosoft/soft2024/conda/anaconda_23.4.7/envs/flask2024/lib/python3.9/site-packages/gunicorn/http/unreader.py", line 37, in read
    d = self.chunk()
  File "/data/biosoft/soft2024/conda/anaconda_23.4.7/envs/flask2024/lib/python3.9/site-packages/gunicorn/http/unreader.py", line 64, in chunk
    return self.sock.recv(self.mxchunk)
  File "/data/biosoft/soft2024/conda/anaconda_23.4.7/envs/flask2024/lib/python3.9/site-packages/gunicorn/workers/base.py", line 203, in handle_abort
    sys.exit(1)
SystemExit: 1
[2024-06-04 14:19:08 +0800] [316991] [ERROR] Worker (pid:316992) was sent SIGINT!
[2024-06-04 14:19:08 +0800] [316991] [ERROR] Worker (pid:317040) was sent SIGINT!
[2024-06-04 14:19:08 +0800] [316991] [ERROR] Worker (pid:317041) was sent SIGINT!
[2024-06-04 14:19:08 +0800] [316991] [ERROR] Worker (pid:317042) was sent SIGINT!
[2024-06-04 14:19:08 +0800] [316991] [ERROR] Worker (pid:317044) was sent SIGINT!
[2024-06-04 14:19:08 +0800] [316991] [ERROR] Worker (pid:317092) was sent SIGINT!
[2024-06-04 14:19:08 +0800] [316991] [ERROR] Worker (pid:317043) was sent SIGINT!
[2024-06-04 14:19:08 +0800] [316991] [ERROR] Worker (pid:317093) was sent SIGINT!
[2024-06-04 14:19:25,000] ERROR in app: Exception on /hidden/20240604141917-74b6c3a4-19a0-473f-99ec-14da554be495 [GET]
Traceback (most recent call last):
  File "/data/biosoft/soft2024/conda/anaconda_23.4.7/envs/flask2024/lib/python3.9/site-packages/flask/app.py", line 1473, in wsgi_app
    response = self.full_dispatch_request()
  File "/data/biosoft/soft2024/conda/anaconda_23.4.7/envs/flask2024/lib/python3.9/site-packages/flask/app.py", line 882, in full_dispatch_request
    rv = self.handle_user_exception(e)
  File "/data/biosoft/soft2024/conda/anaconda_23.4.7/envs/flask2024/lib/python3.9/site-packages/flask/app.py", line 880, in full_dispatch_request
    rv = self.dispatch_request()
  File "/data/biosoft/soft2024/conda/anaconda_23.4.7/envs/flask2024/lib/python3.9/site-packages/flask/app.py", line 865, in dispatch_request
    return self.ensure_sync(self.view_functions[rule.endpoint])(**view_args)  # type: ignore[no-any-return]
  File "/data/cailab/flask2024/demo/blueprint/hidden.py", line 20, in hidden
    if not session.get('logged_in'):  # 检查session
NameError: name 'session' is not defined
[2024-06-04 14:19:55 +0800] [320028] [CRITICAL] WORKER TIMEOUT (pid:320059)
[2024-06-04 14:19:55 +0800] [320059] [ERROR] Error handling request (no URI read)
Traceback (most recent call last):
  File "/data/biosoft/soft2024/conda/anaconda_23.4.7/envs/flask2024/lib/python3.9/site-packages/gunicorn/workers/sync.py", line 134, in handle
    req = next(parser)
  File "/data/biosoft/soft2024/conda/anaconda_23.4.7/envs/flask2024/lib/python3.9/site-packages/gunicorn/http/parser.py", line 42, in __next__
    self.mesg = self.mesg_class(self.cfg, self.unreader, self.source_addr, self.req_count)
  File "/data/biosoft/soft2024/conda/anaconda_23.4.7/envs/flask2024/lib/python3.9/site-packages/gunicorn/http/message.py", line 257, in __init__
    super().__init__(cfg, unreader, peer_addr)
  File "/data/biosoft/soft2024/conda/anaconda_23.4.7/envs/flask2024/lib/python3.9/site-packages/gunicorn/http/message.py", line 60, in __init__
    unused = self.parse(self.unreader)
  File "/data/biosoft/soft2024/conda/anaconda_23.4.7/envs/flask2024/lib/python3.9/site-packages/gunicorn/http/message.py", line 269, in parse
    self.get_data(unreader, buf, stop=True)
  File "/data/biosoft/soft2024/conda/anaconda_23.4.7/envs/flask2024/lib/python3.9/site-packages/gunicorn/http/message.py", line 260, in get_data
    data = unreader.read()
  File "/data/biosoft/soft2024/conda/anaconda_23.4.7/envs/flask2024/lib/python3.9/site-packages/gunicorn/http/unreader.py", line 37, in read
    d = self.chunk()
  File "/data/biosoft/soft2024/conda/anaconda_23.4.7/envs/flask2024/lib/python3.9/site-packages/gunicorn/http/unreader.py", line 64, in chunk
    return self.sock.recv(self.mxchunk)
  File "/data/biosoft/soft2024/conda/anaconda_23.4.7/envs/flask2024/lib/python3.9/site-packages/gunicorn/workers/base.py", line 203, in handle_abort
    sys.exit(1)
SystemExit: 1
[2024-06-04 14:20:41 +0800] [320028] [CRITICAL] WORKER TIMEOUT (pid:320060)
[2024-06-04 14:20:41 +0800] [320060] [ERROR] Error handling request (no URI read)
Traceback (most recent call last):
  File "/data/biosoft/soft2024/conda/anaconda_23.4.7/envs/flask2024/lib/python3.9/site-packages/gunicorn/workers/sync.py", line 134, in handle
    req = next(parser)
  File "/data/biosoft/soft2024/conda/anaconda_23.4.7/envs/flask2024/lib/python3.9/site-packages/gunicorn/http/parser.py", line 42, in __next__
    self.mesg = self.mesg_class(self.cfg, self.unreader, self.source_addr, self.req_count)
  File "/data/biosoft/soft2024/conda/anaconda_23.4.7/envs/flask2024/lib/python3.9/site-packages/gunicorn/http/message.py", line 257, in __init__
    super().__init__(cfg, unreader, peer_addr)
  File "/data/biosoft/soft2024/conda/anaconda_23.4.7/envs/flask2024/lib/python3.9/site-packages/gunicorn/http/message.py", line 60, in __init__
    unused = self.parse(self.unreader)
  File "/data/biosoft/soft2024/conda/anaconda_23.4.7/envs/flask2024/lib/python3.9/site-packages/gunicorn/http/message.py", line 269, in parse
    self.get_data(unreader, buf, stop=True)
  File "/data/biosoft/soft2024/conda/anaconda_23.4.7/envs/flask2024/lib/python3.9/site-packages/gunicorn/http/message.py", line 260, in get_data
    data = unreader.read()
  File "/data/biosoft/soft2024/conda/anaconda_23.4.7/envs/flask2024/lib/python3.9/site-packages/gunicorn/http/unreader.py", line 37, in read
    d = self.chunk()
  File "/data/biosoft/soft2024/conda/anaconda_23.4.7/envs/flask2024/lib/python3.9/site-packages/gunicorn/http/unreader.py", line 64, in chunk
    return self.sock.recv(self.mxchunk)
  File "/data/biosoft/soft2024/conda/anaconda_23.4.7/envs/flask2024/lib/python3.9/site-packages/gunicorn/workers/base.py", line 203, in handle_abort
    sys.exit(1)
SystemExit: 1
[2024-06-04 14:24:07,454] ERROR in app: Exception on /login [POST]
Traceback (most recent call last):
  File "/data/biosoft/soft2024/conda/anaconda_23.4.7/envs/flask2024/lib/python3.9/site-packages/flask/app.py", line 1473, in wsgi_app
    response = self.full_dispatch_request()
  File "/data/biosoft/soft2024/conda/anaconda_23.4.7/envs/flask2024/lib/python3.9/site-packages/flask/app.py", line 882, in full_dispatch_request
    rv = self.handle_user_exception(e)
  File "/data/biosoft/soft2024/conda/anaconda_23.4.7/envs/flask2024/lib/python3.9/site-packages/flask/app.py", line 880, in full_dispatch_request
    rv = self.dispatch_request()
  File "/data/biosoft/soft2024/conda/anaconda_23.4.7/envs/flask2024/lib/python3.9/site-packages/flask/app.py", line 865, in dispatch_request
    return self.ensure_sync(self.view_functions[rule.endpoint])(**view_args)  # type: ignore[no-any-return]
  File "/data/cailab/flask2024/demo/blueprint/hidden.py", line 10, in login
    task_id = request.form['task_id']  # 确保从表单获取task_id
NameError: name 'request' is not defined
[2024-06-04 14:24:38 +0800] [321441] [CRITICAL] WORKER TIMEOUT (pid:321637)
[2024-06-04 14:24:38 +0800] [321637] [ERROR] Error handling request (no URI read)
Traceback (most recent call last):
  File "/data/biosoft/soft2024/conda/anaconda_23.4.7/envs/flask2024/lib/python3.9/site-packages/gunicorn/workers/sync.py", line 134, in handle
    req = next(parser)
  File "/data/biosoft/soft2024/conda/anaconda_23.4.7/envs/flask2024/lib/python3.9/site-packages/gunicorn/http/parser.py", line 42, in __next__
    self.mesg = self.mesg_class(self.cfg, self.unreader, self.source_addr, self.req_count)
  File "/data/biosoft/soft2024/conda/anaconda_23.4.7/envs/flask2024/lib/python3.9/site-packages/gunicorn/http/message.py", line 257, in __init__
    super().__init__(cfg, unreader, peer_addr)
  File "/data/biosoft/soft2024/conda/anaconda_23.4.7/envs/flask2024/lib/python3.9/site-packages/gunicorn/http/message.py", line 60, in __init__
    unused = self.parse(self.unreader)
  File "/data/biosoft/soft2024/conda/anaconda_23.4.7/envs/flask2024/lib/python3.9/site-packages/gunicorn/http/message.py", line 269, in parse
    self.get_data(unreader, buf, stop=True)
  File "/data/biosoft/soft2024/conda/anaconda_23.4.7/envs/flask2024/lib/python3.9/site-packages/gunicorn/http/message.py", line 260, in get_data
    data = unreader.read()
  File "/data/biosoft/soft2024/conda/anaconda_23.4.7/envs/flask2024/lib/python3.9/site-packages/gunicorn/http/unreader.py", line 37, in read
    d = self.chunk()
  File "/data/biosoft/soft2024/conda/anaconda_23.4.7/envs/flask2024/lib/python3.9/site-packages/gunicorn/http/unreader.py", line 64, in chunk
    return self.sock.recv(self.mxchunk)
  File "/data/biosoft/soft2024/conda/anaconda_23.4.7/envs/flask2024/lib/python3.9/site-packages/gunicorn/workers/base.py", line 203, in handle_abort
    sys.exit(1)
SystemExit: 1
[2024-06-04 14:26:10,032] ERROR in app: Exception on /login [POST]
Traceback (most recent call last):
  File "/data/biosoft/soft2024/conda/anaconda_23.4.7/envs/flask2024/lib/python3.9/site-packages/flask/app.py", line 1473, in wsgi_app
    response = self.full_dispatch_request()
  File "/data/biosoft/soft2024/conda/anaconda_23.4.7/envs/flask2024/lib/python3.9/site-packages/flask/app.py", line 882, in full_dispatch_request
    rv = self.handle_user_exception(e)
  File "/data/biosoft/soft2024/conda/anaconda_23.4.7/envs/flask2024/lib/python3.9/site-packages/flask/app.py", line 880, in full_dispatch_request
    rv = self.dispatch_request()
  File "/data/biosoft/soft2024/conda/anaconda_23.4.7/envs/flask2024/lib/python3.9/site-packages/flask/app.py", line 865, in dispatch_request
    return self.ensure_sync(self.view_functions[rule.endpoint])(**view_args)  # type: ignore[no-any-return]
  File "/data/cailab/flask2024/demo/blueprint/hidden.py", line 27, in login
    return redirect(url_for('hidden_bp.hidden', task_id=task_id))
  File "/data/biosoft/soft2024/conda/anaconda_23.4.7/envs/flask2024/lib/python3.9/site-packages/flask/helpers.py", line 220, in url_for
    return current_app.url_for(
  File "/data/biosoft/soft2024/conda/anaconda_23.4.7/envs/flask2024/lib/python3.9/site-packages/flask/app.py", line 1084, in url_for
    return self.handle_url_build_error(error, endpoint, values)
  File "/data/biosoft/soft2024/conda/anaconda_23.4.7/envs/flask2024/lib/python3.9/site-packages/flask/app.py", line 1073, in url_for
    rv = url_adapter.build(  # type: ignore[union-attr]
  File "/data/biosoft/soft2024/conda/anaconda_23.4.7/envs/flask2024/lib/python3.9/site-packages/werkzeug/routing/map.py", line 926, in build
    raise BuildError(endpoint, values, method, self)
werkzeug.routing.exceptions.BuildError: Could not build url for endpoint 'hidden_bp.hidden' with values ['task_id']. Did you mean 'hidden.hidden' instead?
[2024-06-04 14:26:40 +0800] [322523] [CRITICAL] WORKER TIMEOUT (pid:322573)
[2024-06-04 14:26:40 +0800] [322573] [ERROR] Error handling request (no URI read)
Traceback (most recent call last):
  File "/data/biosoft/soft2024/conda/anaconda_23.4.7/envs/flask2024/lib/python3.9/site-packages/gunicorn/workers/sync.py", line 134, in handle
    req = next(parser)
  File "/data/biosoft/soft2024/conda/anaconda_23.4.7/envs/flask2024/lib/python3.9/site-packages/gunicorn/http/parser.py", line 42, in __next__
    self.mesg = self.mesg_class(self.cfg, self.unreader, self.source_addr, self.req_count)
  File "/data/biosoft/soft2024/conda/anaconda_23.4.7/envs/flask2024/lib/python3.9/site-packages/gunicorn/http/message.py", line 257, in __init__
    super().__init__(cfg, unreader, peer_addr)
  File "/data/biosoft/soft2024/conda/anaconda_23.4.7/envs/flask2024/lib/python3.9/site-packages/gunicorn/http/message.py", line 60, in __init__
    unused = self.parse(self.unreader)
  File "/data/biosoft/soft2024/conda/anaconda_23.4.7/envs/flask2024/lib/python3.9/site-packages/gunicorn/http/message.py", line 269, in parse
    self.get_data(unreader, buf, stop=True)
  File "/data/biosoft/soft2024/conda/anaconda_23.4.7/envs/flask2024/lib/python3.9/site-packages/gunicorn/http/message.py", line 260, in get_data
    data = unreader.read()
  File "/data/biosoft/soft2024/conda/anaconda_23.4.7/envs/flask2024/lib/python3.9/site-packages/gunicorn/http/unreader.py", line 37, in read
    d = self.chunk()
  File "/data/biosoft/soft2024/conda/anaconda_23.4.7/envs/flask2024/lib/python3.9/site-packages/gunicorn/http/unreader.py", line 64, in chunk
    return self.sock.recv(self.mxchunk)
  File "/data/biosoft/soft2024/conda/anaconda_23.4.7/envs/flask2024/lib/python3.9/site-packages/gunicorn/workers/base.py", line 203, in handle_abort
    sys.exit(1)
SystemExit: 1
[2024-06-04 14:27:36 +0800] [323109] [CRITICAL] WORKER TIMEOUT (pid:323257)
[2024-06-04 14:27:36 +0800] [323257] [ERROR] Error handling request (no URI read)
Traceback (most recent call last):
  File "/data/biosoft/soft2024/conda/anaconda_23.4.7/envs/flask2024/lib/python3.9/site-packages/gunicorn/workers/sync.py", line 134, in handle
    req = next(parser)
  File "/data/biosoft/soft2024/conda/anaconda_23.4.7/envs/flask2024/lib/python3.9/site-packages/gunicorn/http/parser.py", line 42, in __next__
    self.mesg = self.mesg_class(self.cfg, self.unreader, self.source_addr, self.req_count)
  File "/data/biosoft/soft2024/conda/anaconda_23.4.7/envs/flask2024/lib/python3.9/site-packages/gunicorn/http/message.py", line 257, in __init__
    super().__init__(cfg, unreader, peer_addr)
  File "/data/biosoft/soft2024/conda/anaconda_23.4.7/envs/flask2024/lib/python3.9/site-packages/gunicorn/http/message.py", line 60, in __init__
    unused = self.parse(self.unreader)
  File "/data/biosoft/soft2024/conda/anaconda_23.4.7/envs/flask2024/lib/python3.9/site-packages/gunicorn/http/message.py", line 269, in parse
    self.get_data(unreader, buf, stop=True)
  File "/data/biosoft/soft2024/conda/anaconda_23.4.7/envs/flask2024/lib/python3.9/site-packages/gunicorn/http/message.py", line 260, in get_data
    data = unreader.read()
  File "/data/biosoft/soft2024/conda/anaconda_23.4.7/envs/flask2024/lib/python3.9/site-packages/gunicorn/http/unreader.py", line 37, in read
    d = self.chunk()
  File "/data/biosoft/soft2024/conda/anaconda_23.4.7/envs/flask2024/lib/python3.9/site-packages/gunicorn/http/unreader.py", line 64, in chunk
    return self.sock.recv(self.mxchunk)
  File "/data/biosoft/soft2024/conda/anaconda_23.4.7/envs/flask2024/lib/python3.9/site-packages/gunicorn/workers/base.py", line 203, in handle_abort
    sys.exit(1)
SystemExit: 1
[2024-06-04 14:33:57,807] ERROR in app: Exception on /hidden/1231 [GET]
Traceback (most recent call last):
  File "/data/biosoft/soft2024/conda/anaconda_23.4.7/envs/flask2024/lib/python3.9/site-packages/flask/app.py", line 1473, in wsgi_app
    response = self.full_dispatch_request()
  File "/data/biosoft/soft2024/conda/anaconda_23.4.7/envs/flask2024/lib/python3.9/site-packages/flask/app.py", line 882, in full_dispatch_request
    rv = self.handle_user_exception(e)
  File "/data/biosoft/soft2024/conda/anaconda_23.4.7/envs/flask2024/lib/python3.9/site-packages/flask/app.py", line 880, in full_dispatch_request
    rv = self.dispatch_request()
  File "/data/biosoft/soft2024/conda/anaconda_23.4.7/envs/flask2024/lib/python3.9/site-packages/flask/app.py", line 865, in dispatch_request
    return self.ensure_sync(self.view_functions[rule.endpoint])(**view_args)  # type: ignore[no-any-return]
  File "/data/cailab/flask2024/demo/blueprint/hidden.py", line 33, in hidden
    return redirect(url_for('biology/home.html', task_id=task_id))
  File "/data/biosoft/soft2024/conda/anaconda_23.4.7/envs/flask2024/lib/python3.9/site-packages/flask/helpers.py", line 220, in url_for
    return current_app.url_for(
  File "/data/biosoft/soft2024/conda/anaconda_23.4.7/envs/flask2024/lib/python3.9/site-packages/flask/app.py", line 1084, in url_for
    return self.handle_url_build_error(error, endpoint, values)
  File "/data/biosoft/soft2024/conda/anaconda_23.4.7/envs/flask2024/lib/python3.9/site-packages/flask/app.py", line 1073, in url_for
    rv = url_adapter.build(  # type: ignore[union-attr]
  File "/data/biosoft/soft2024/conda/anaconda_23.4.7/envs/flask2024/lib/python3.9/site-packages/werkzeug/routing/map.py", line 926, in build
    raise BuildError(endpoint, values, method, self)
werkzeug.routing.exceptions.BuildError: Could not build url for endpoint 'biology/home.html' with values ['task_id']. Did you mean 'biology.home' instead?
[2024-06-04 14:34:31,847] ERROR in app: Exception on /hidden/20240604143411-7594270e-fc14-4cb7-afb6-8681c23d747a [GET]
Traceback (most recent call last):
  File "/data/biosoft/soft2024/conda/anaconda_23.4.7/envs/flask2024/lib/python3.9/site-packages/flask/app.py", line 1473, in wsgi_app
    response = self.full_dispatch_request()
  File "/data/biosoft/soft2024/conda/anaconda_23.4.7/envs/flask2024/lib/python3.9/site-packages/flask/app.py", line 882, in full_dispatch_request
    rv = self.handle_user_exception(e)
  File "/data/biosoft/soft2024/conda/anaconda_23.4.7/envs/flask2024/lib/python3.9/site-packages/flask/app.py", line 880, in full_dispatch_request
    rv = self.dispatch_request()
  File "/data/biosoft/soft2024/conda/anaconda_23.4.7/envs/flask2024/lib/python3.9/site-packages/flask/app.py", line 865, in dispatch_request
    return self.ensure_sync(self.view_functions[rule.endpoint])(**view_args)  # type: ignore[no-any-return]
  File "/data/cailab/flask2024/demo/blueprint/hidden.py", line 33, in hidden
    return redirect(url_for('biology/home.html', task_id=task_id))
  File "/data/biosoft/soft2024/conda/anaconda_23.4.7/envs/flask2024/lib/python3.9/site-packages/flask/helpers.py", line 220, in url_for
    return current_app.url_for(
  File "/data/biosoft/soft2024/conda/anaconda_23.4.7/envs/flask2024/lib/python3.9/site-packages/flask/app.py", line 1084, in url_for
    return self.handle_url_build_error(error, endpoint, values)
  File "/data/biosoft/soft2024/conda/anaconda_23.4.7/envs/flask2024/lib/python3.9/site-packages/flask/app.py", line 1073, in url_for
    rv = url_adapter.build(  # type: ignore[union-attr]
  File "/data/biosoft/soft2024/conda/anaconda_23.4.7/envs/flask2024/lib/python3.9/site-packages/werkzeug/routing/map.py", line 926, in build
    raise BuildError(endpoint, values, method, self)
werkzeug.routing.exceptions.BuildError: Could not build url for endpoint 'biology/home.html' with values ['task_id']. Did you mean 'biology.home' instead?
[2024-06-04 14:34:39,459] ERROR in app: Exception on /hidden/20240604143411-7594270e-fc14-4cb7-afb6-8681c23d747a [GET]
Traceback (most recent call last):
  File "/data/biosoft/soft2024/conda/anaconda_23.4.7/envs/flask2024/lib/python3.9/site-packages/flask/app.py", line 1473, in wsgi_app
    response = self.full_dispatch_request()
  File "/data/biosoft/soft2024/conda/anaconda_23.4.7/envs/flask2024/lib/python3.9/site-packages/flask/app.py", line 882, in full_dispatch_request
    rv = self.handle_user_exception(e)
  File "/data/biosoft/soft2024/conda/anaconda_23.4.7/envs/flask2024/lib/python3.9/site-packages/flask/app.py", line 880, in full_dispatch_request
    rv = self.dispatch_request()
  File "/data/biosoft/soft2024/conda/anaconda_23.4.7/envs/flask2024/lib/python3.9/site-packages/flask/app.py", line 865, in dispatch_request
    return self.ensure_sync(self.view_functions[rule.endpoint])(**view_args)  # type: ignore[no-any-return]
  File "/data/cailab/flask2024/demo/blueprint/hidden.py", line 33, in hidden
    return redirect(url_for('biology/home.html', task_id=task_id))
  File "/data/biosoft/soft2024/conda/anaconda_23.4.7/envs/flask2024/lib/python3.9/site-packages/flask/helpers.py", line 220, in url_for
    return current_app.url_for(
  File "/data/biosoft/soft2024/conda/anaconda_23.4.7/envs/flask2024/lib/python3.9/site-packages/flask/app.py", line 1084, in url_for
    return self.handle_url_build_error(error, endpoint, values)
  File "/data/biosoft/soft2024/conda/anaconda_23.4.7/envs/flask2024/lib/python3.9/site-packages/flask/app.py", line 1073, in url_for
    rv = url_adapter.build(  # type: ignore[union-attr]
  File "/data/biosoft/soft2024/conda/anaconda_23.4.7/envs/flask2024/lib/python3.9/site-packages/werkzeug/routing/map.py", line 926, in build
    raise BuildError(endpoint, values, method, self)
werkzeug.routing.exceptions.BuildError: Could not build url for endpoint 'biology/home.html' with values ['task_id']. Did you mean 'biology.home' instead?
[2024-06-04 14:35:09 +0800] [326422] [CRITICAL] WORKER TIMEOUT (pid:326475)
[2024-06-04 14:35:09 +0800] [326475] [ERROR] Error handling request (no URI read)
Traceback (most recent call last):
  File "/data/biosoft/soft2024/conda/anaconda_23.4.7/envs/flask2024/lib/python3.9/site-packages/gunicorn/workers/sync.py", line 134, in handle
    req = next(parser)
  File "/data/biosoft/soft2024/conda/anaconda_23.4.7/envs/flask2024/lib/python3.9/site-packages/gunicorn/http/parser.py", line 42, in __next__
    self.mesg = self.mesg_class(self.cfg, self.unreader, self.source_addr, self.req_count)
  File "/data/biosoft/soft2024/conda/anaconda_23.4.7/envs/flask2024/lib/python3.9/site-packages/gunicorn/http/message.py", line 257, in __init__
    super().__init__(cfg, unreader, peer_addr)
  File "/data/biosoft/soft2024/conda/anaconda_23.4.7/envs/flask2024/lib/python3.9/site-packages/gunicorn/http/message.py", line 60, in __init__
    unused = self.parse(self.unreader)
  File "/data/biosoft/soft2024/conda/anaconda_23.4.7/envs/flask2024/lib/python3.9/site-packages/gunicorn/http/message.py", line 269, in parse
    self.get_data(unreader, buf, stop=True)
  File "/data/biosoft/soft2024/conda/anaconda_23.4.7/envs/flask2024/lib/python3.9/site-packages/gunicorn/http/message.py", line 260, in get_data
    data = unreader.read()
  File "/data/biosoft/soft2024/conda/anaconda_23.4.7/envs/flask2024/lib/python3.9/site-packages/gunicorn/http/unreader.py", line 37, in read
    d = self.chunk()
  File "/data/biosoft/soft2024/conda/anaconda_23.4.7/envs/flask2024/lib/python3.9/site-packages/gunicorn/http/unreader.py", line 64, in chunk
    return self.sock.recv(self.mxchunk)
  File "/data/biosoft/soft2024/conda/anaconda_23.4.7/envs/flask2024/lib/python3.9/site-packages/gunicorn/workers/base.py", line 203, in handle_abort
    sys.exit(1)
SystemExit: 1
[2024-06-04 14:40:56 +0800] [328259] [CRITICAL] WORKER TIMEOUT (pid:328359)
[2024-06-04 14:40:56 +0800] [328359] [ERROR] Error handling request (no URI read)
Traceback (most recent call last):
  File "/data/biosoft/soft2024/conda/anaconda_23.4.7/envs/flask2024/lib/python3.9/site-packages/gunicorn/workers/sync.py", line 134, in handle
    req = next(parser)
  File "/data/biosoft/soft2024/conda/anaconda_23.4.7/envs/flask2024/lib/python3.9/site-packages/gunicorn/http/parser.py", line 42, in __next__
    self.mesg = self.mesg_class(self.cfg, self.unreader, self.source_addr, self.req_count)
  File "/data/biosoft/soft2024/conda/anaconda_23.4.7/envs/flask2024/lib/python3.9/site-packages/gunicorn/http/message.py", line 257, in __init__
    super().__init__(cfg, unreader, peer_addr)
  File "/data/biosoft/soft2024/conda/anaconda_23.4.7/envs/flask2024/lib/python3.9/site-packages/gunicorn/http/message.py", line 60, in __init__
    unused = self.parse(self.unreader)
  File "/data/biosoft/soft2024/conda/anaconda_23.4.7/envs/flask2024/lib/python3.9/site-packages/gunicorn/http/message.py", line 269, in parse
    self.get_data(unreader, buf, stop=True)
  File "/data/biosoft/soft2024/conda/anaconda_23.4.7/envs/flask2024/lib/python3.9/site-packages/gunicorn/http/message.py", line 260, in get_data
    data = unreader.read()
  File "/data/biosoft/soft2024/conda/anaconda_23.4.7/envs/flask2024/lib/python3.9/site-packages/gunicorn/http/unreader.py", line 37, in read
    d = self.chunk()
  File "/data/biosoft/soft2024/conda/anaconda_23.4.7/envs/flask2024/lib/python3.9/site-packages/gunicorn/http/unreader.py", line 64, in chunk
    return self.sock.recv(self.mxchunk)
  File "/data/biosoft/soft2024/conda/anaconda_23.4.7/envs/flask2024/lib/python3.9/site-packages/gunicorn/workers/base.py", line 203, in handle_abort
    sys.exit(1)
SystemExit: 1
[2024-06-04 14:49:01,636] ERROR in app: Exception on /check/46444 [POST]
Traceback (most recent call last):
  File "/data/biosoft/soft2024/conda/anaconda_23.4.7/envs/flask2024/lib/python3.9/site-packages/flask/app.py", line 1473, in wsgi_app
    response = self.full_dispatch_request()
  File "/data/biosoft/soft2024/conda/anaconda_23.4.7/envs/flask2024/lib/python3.9/site-packages/flask/app.py", line 882, in full_dispatch_request
    rv = self.handle_user_exception(e)
  File "/data/biosoft/soft2024/conda/anaconda_23.4.7/envs/flask2024/lib/python3.9/site-packages/flask/app.py", line 880, in full_dispatch_request
    rv = self.dispatch_request()
  File "/data/biosoft/soft2024/conda/anaconda_23.4.7/envs/flask2024/lib/python3.9/site-packages/flask/app.py", line 865, in dispatch_request
    return self.ensure_sync(self.view_functions[rule.endpoint])(**view_args)  # type: ignore[no-any-return]
  File "/data/cailab/flask2024/demo/blueprint/biology.py", line 61, in check
    fastqs = get_fq_list(selected_folder, info["mode"] != "single")
  File "/data/cailab/flask2024/demo/blueprint/modules/utils.py", line 69, in get_fq_list
    for file in os.listdir(indir):
FileNotFoundError: [Errno 2] No such file or directory: 'no input'
[2024-06-04 14:49:47 +0800] [328259] [CRITICAL] WORKER TIMEOUT (pid:328261)
[2024-06-04 14:49:47 +0800] [328261] [ERROR] Error handling request (no URI read)
Traceback (most recent call last):
  File "/data/biosoft/soft2024/conda/anaconda_23.4.7/envs/flask2024/lib/python3.9/site-packages/gunicorn/workers/sync.py", line 134, in handle
    req = next(parser)
  File "/data/biosoft/soft2024/conda/anaconda_23.4.7/envs/flask2024/lib/python3.9/site-packages/gunicorn/http/parser.py", line 42, in __next__
    self.mesg = self.mesg_class(self.cfg, self.unreader, self.source_addr, self.req_count)
  File "/data/biosoft/soft2024/conda/anaconda_23.4.7/envs/flask2024/lib/python3.9/site-packages/gunicorn/http/message.py", line 257, in __init__
    super().__init__(cfg, unreader, peer_addr)
  File "/data/biosoft/soft2024/conda/anaconda_23.4.7/envs/flask2024/lib/python3.9/site-packages/gunicorn/http/message.py", line 60, in __init__
    unused = self.parse(self.unreader)
  File "/data/biosoft/soft2024/conda/anaconda_23.4.7/envs/flask2024/lib/python3.9/site-packages/gunicorn/http/message.py", line 269, in parse
    self.get_data(unreader, buf, stop=True)
  File "/data/biosoft/soft2024/conda/anaconda_23.4.7/envs/flask2024/lib/python3.9/site-packages/gunicorn/http/message.py", line 260, in get_data
    data = unreader.read()
  File "/data/biosoft/soft2024/conda/anaconda_23.4.7/envs/flask2024/lib/python3.9/site-packages/gunicorn/http/unreader.py", line 37, in read
    d = self.chunk()
  File "/data/biosoft/soft2024/conda/anaconda_23.4.7/envs/flask2024/lib/python3.9/site-packages/gunicorn/http/unreader.py", line 64, in chunk
    return self.sock.recv(self.mxchunk)
  File "/data/biosoft/soft2024/conda/anaconda_23.4.7/envs/flask2024/lib/python3.9/site-packages/gunicorn/workers/base.py", line 203, in handle_abort
    sys.exit(1)
SystemExit: 1
[2024-06-04 14:52:55 +0800] [328259] [CRITICAL] WORKER TIMEOUT (pid:328357)
[2024-06-04 14:52:55 +0800] [328357] [ERROR] Error handling request (no URI read)
Traceback (most recent call last):
  File "/data/biosoft/soft2024/conda/anaconda_23.4.7/envs/flask2024/lib/python3.9/site-packages/gunicorn/workers/sync.py", line 134, in handle
    req = next(parser)
  File "/data/biosoft/soft2024/conda/anaconda_23.4.7/envs/flask2024/lib/python3.9/site-packages/gunicorn/http/parser.py", line 42, in __next__
    self.mesg = self.mesg_class(self.cfg, self.unreader, self.source_addr, self.req_count)
  File "/data/biosoft/soft2024/conda/anaconda_23.4.7/envs/flask2024/lib/python3.9/site-packages/gunicorn/http/message.py", line 257, in __init__
    super().__init__(cfg, unreader, peer_addr)
  File "/data/biosoft/soft2024/conda/anaconda_23.4.7/envs/flask2024/lib/python3.9/site-packages/gunicorn/http/message.py", line 60, in __init__
    unused = self.parse(self.unreader)
  File "/data/biosoft/soft2024/conda/anaconda_23.4.7/envs/flask2024/lib/python3.9/site-packages/gunicorn/http/message.py", line 269, in parse
    self.get_data(unreader, buf, stop=True)
  File "/data/biosoft/soft2024/conda/anaconda_23.4.7/envs/flask2024/lib/python3.9/site-packages/gunicorn/http/message.py", line 260, in get_data
    data = unreader.read()
  File "/data/biosoft/soft2024/conda/anaconda_23.4.7/envs/flask2024/lib/python3.9/site-packages/gunicorn/http/unreader.py", line 37, in read
    d = self.chunk()
  File "/data/biosoft/soft2024/conda/anaconda_23.4.7/envs/flask2024/lib/python3.9/site-packages/gunicorn/http/unreader.py", line 64, in chunk
    return self.sock.recv(self.mxchunk)
  File "/data/biosoft/soft2024/conda/anaconda_23.4.7/envs/flask2024/lib/python3.9/site-packages/gunicorn/workers/base.py", line 203, in handle_abort
    sys.exit(1)
SystemExit: 1
[2024-06-04 14:54:38 +0800] [328259] [CRITICAL] WORKER TIMEOUT (pid:328358)
[2024-06-04 14:54:38 +0800] [328358] [ERROR] Error handling request (no URI read)
Traceback (most recent call last):
  File "/data/biosoft/soft2024/conda/anaconda_23.4.7/envs/flask2024/lib/python3.9/site-packages/gunicorn/workers/sync.py", line 134, in handle
    req = next(parser)
  File "/data/biosoft/soft2024/conda/anaconda_23.4.7/envs/flask2024/lib/python3.9/site-packages/gunicorn/http/parser.py", line 42, in __next__
    self.mesg = self.mesg_class(self.cfg, self.unreader, self.source_addr, self.req_count)
  File "/data/biosoft/soft2024/conda/anaconda_23.4.7/envs/flask2024/lib/python3.9/site-packages/gunicorn/http/message.py", line 257, in __init__
    super().__init__(cfg, unreader, peer_addr)
  File "/data/biosoft/soft2024/conda/anaconda_23.4.7/envs/flask2024/lib/python3.9/site-packages/gunicorn/http/message.py", line 60, in __init__
    unused = self.parse(self.unreader)
  File "/data/biosoft/soft2024/conda/anaconda_23.4.7/envs/flask2024/lib/python3.9/site-packages/gunicorn/http/message.py", line 269, in parse
    self.get_data(unreader, buf, stop=True)
  File "/data/biosoft/soft2024/conda/anaconda_23.4.7/envs/flask2024/lib/python3.9/site-packages/gunicorn/http/message.py", line 260, in get_data
    data = unreader.read()
  File "/data/biosoft/soft2024/conda/anaconda_23.4.7/envs/flask2024/lib/python3.9/site-packages/gunicorn/http/unreader.py", line 37, in read
    d = self.chunk()
  File "/data/biosoft/soft2024/conda/anaconda_23.4.7/envs/flask2024/lib/python3.9/site-packages/gunicorn/http/unreader.py", line 64, in chunk
    return self.sock.recv(self.mxchunk)
  File "/data/biosoft/soft2024/conda/anaconda_23.4.7/envs/flask2024/lib/python3.9/site-packages/gunicorn/workers/base.py", line 203, in handle_abort
    sys.exit(1)
SystemExit: 1
[2024-06-04 15:07:38 +0800] [328259] [ERROR] Worker (pid:331334) was sent SIGHUP!
[2024-06-04 15:07:38 +0800] [328259] [ERROR] Worker (pid:328260) was sent SIGHUP!
[2024-06-04 15:07:38 +0800] [328259] [ERROR] Worker (pid:328360) was sent SIGHUP!
[2024-06-04 15:07:38 +0800] [328259] [ERROR] Worker (pid:328309) was sent SIGHUP!
[2024-06-04 15:07:38 +0800] [328259] [ERROR] Worker (pid:332346) was sent SIGHUP!
[2024-06-04 15:07:38 +0800] [328259] [ERROR] Worker (pid:331981) was sent SIGHUP!
[2024-06-04 15:07:38 +0800] [328259] [ERROR] Worker (pid:329655) was sent SIGHUP!
[2024-06-04 15:07:38 +0800] [328259] [ERROR] Worker (pid:328455) was sent SIGHUP!
[2024-06-04 15:07:39 +0800] [328259] [ERROR] Worker (pid:337370) was sent SIGTERM!
[2024-06-04 15:07:39 +0800] [328259] [ERROR] Worker (pid:337371) was sent SIGTERM!
[2024-06-04 15:07:39 +0800] [328259] [ERROR] Worker (pid:337367) was sent SIGTERM!
[2024-06-04 15:07:39 +0800] [328259] [ERROR] Worker (pid:337365) was sent SIGTERM!
[2024-06-04 15:07:39 +0800] [328259] [ERROR] Worker (pid:337368) was sent SIGTERM!
[2024-06-04 15:07:39 +0800] [328259] [ERROR] Worker (pid:337372) was sent SIGTERM!
[2024-06-04 15:07:39 +0800] [328259] [ERROR] Worker (pid:337366) was sent SIGTERM!
[2024-06-04 15:37:04 +0800] [328259] [CRITICAL] WORKER TIMEOUT (pid:337373)
[2024-06-04 15:37:04 +0800] [337373] [ERROR] Error handling request (no URI read)
Traceback (most recent call last):
  File "/data/biosoft/soft2024/conda/anaconda_23.4.7/envs/flask2024/lib/python3.9/site-packages/gunicorn/workers/sync.py", line 134, in handle
    req = next(parser)
  File "/data/biosoft/soft2024/conda/anaconda_23.4.7/envs/flask2024/lib/python3.9/site-packages/gunicorn/http/parser.py", line 42, in __next__
    self.mesg = self.mesg_class(self.cfg, self.unreader, self.source_addr, self.req_count)
  File "/data/biosoft/soft2024/conda/anaconda_23.4.7/envs/flask2024/lib/python3.9/site-packages/gunicorn/http/message.py", line 257, in __init__
    super().__init__(cfg, unreader, peer_addr)
  File "/data/biosoft/soft2024/conda/anaconda_23.4.7/envs/flask2024/lib/python3.9/site-packages/gunicorn/http/message.py", line 60, in __init__
    unused = self.parse(self.unreader)
  File "/data/biosoft/soft2024/conda/anaconda_23.4.7/envs/flask2024/lib/python3.9/site-packages/gunicorn/http/message.py", line 269, in parse
    self.get_data(unreader, buf, stop=True)
  File "/data/biosoft/soft2024/conda/anaconda_23.4.7/envs/flask2024/lib/python3.9/site-packages/gunicorn/http/message.py", line 260, in get_data
    data = unreader.read()
  File "/data/biosoft/soft2024/conda/anaconda_23.4.7/envs/flask2024/lib/python3.9/site-packages/gunicorn/http/unreader.py", line 37, in read
    d = self.chunk()
  File "/data/biosoft/soft2024/conda/anaconda_23.4.7/envs/flask2024/lib/python3.9/site-packages/gunicorn/http/unreader.py", line 64, in chunk
    return self.sock.recv(self.mxchunk)
  File "/data/biosoft/soft2024/conda/anaconda_23.4.7/envs/flask2024/lib/python3.9/site-packages/gunicorn/workers/base.py", line 203, in handle_abort
    sys.exit(1)
SystemExit: 1
[2024-06-14 10:59:19 +0800] [328259] [CRITICAL] WORKER TIMEOUT (pid:337377)
[2024-06-14 10:59:19 +0800] [337377] [ERROR] Error handling request (no URI read)
Traceback (most recent call last):
  File "/data/biosoft/soft2024/conda/anaconda_23.4.7/envs/flask2024/lib/python3.9/site-packages/gunicorn/workers/sync.py", line 134, in handle
    req = next(parser)
  File "/data/biosoft/soft2024/conda/anaconda_23.4.7/envs/flask2024/lib/python3.9/site-packages/gunicorn/http/parser.py", line 42, in __next__
    self.mesg = self.mesg_class(self.cfg, self.unreader, self.source_addr, self.req_count)
  File "/data/biosoft/soft2024/conda/anaconda_23.4.7/envs/flask2024/lib/python3.9/site-packages/gunicorn/http/message.py", line 257, in __init__
    super().__init__(cfg, unreader, peer_addr)
  File "/data/biosoft/soft2024/conda/anaconda_23.4.7/envs/flask2024/lib/python3.9/site-packages/gunicorn/http/message.py", line 60, in __init__
    unused = self.parse(self.unreader)
  File "/data/biosoft/soft2024/conda/anaconda_23.4.7/envs/flask2024/lib/python3.9/site-packages/gunicorn/http/message.py", line 269, in parse
    self.get_data(unreader, buf, stop=True)
  File "/data/biosoft/soft2024/conda/anaconda_23.4.7/envs/flask2024/lib/python3.9/site-packages/gunicorn/http/message.py", line 260, in get_data
    data = unreader.read()
  File "/data/biosoft/soft2024/conda/anaconda_23.4.7/envs/flask2024/lib/python3.9/site-packages/gunicorn/http/unreader.py", line 37, in read
    d = self.chunk()
  File "/data/biosoft/soft2024/conda/anaconda_23.4.7/envs/flask2024/lib/python3.9/site-packages/gunicorn/http/unreader.py", line 64, in chunk
    return self.sock.recv(self.mxchunk)
  File "/data/biosoft/soft2024/conda/anaconda_23.4.7/envs/flask2024/lib/python3.9/site-packages/gunicorn/workers/base.py", line 203, in handle_abort
    sys.exit(1)
SystemExit: 1
[2024-06-14 10:59:20 +0800] [328259] [ERROR] Worker (pid:337377) was sent SIGKILL! Perhaps out of memory?
