[2024-05-27 17:01:00 +0800] [359234] [ERROR] Worker (pid:395394) was sent SIGTERM!
[2024-05-27 17:01:00 +0800] [359234] [ERROR] Worker (pid:395395) was sent SIGTERM!
[2024-05-27 17:01:00 +0800] [359234] [ERROR] Worker (pid:395398) was sent SIGTERM!
[2024-05-27 17:01:00 +0800] [359234] [ERROR] Worker (pid:395399) was sent SIGTERM!
[2024-05-27 17:01:00 +0800] [359234] [ERROR] Worker (pid:395400) was sent SIGTERM!
[2024-05-27 17:01:00 +0800] [359234] [ERROR] Worker (pid:395396) was sent SIGTERM!
[2024-05-27 17:01:00 +0800] [359234] [ERROR] Worker (pid:395397) was sent SIGTERM!
[2024-05-27 17:24:32 +0800] [403644] [CRITICAL] WORKER TIMEOUT (pid:403794)
[2024-05-27 17:24:32 +0800] [403794] [ERROR] Error handling request (no URI read)
Traceback (most recent call last):
  File "/data/biosoft/soft2024/conda/anaconda_23.4.7/envs/flask2024/lib/python3.9/site-packages/gunicorn/workers/sync.py", line 134, in handle
    req = next(parser)
  File "/data/biosoft/soft2024/conda/anaconda_23.4.7/envs/flask2024/lib/python3.9/site-packages/gunicorn/http/parser.py", line 42, in __next__
    self.mesg = self.mesg_class(self.cfg, self.unreader, self.source_addr, self.req_count)
  File "/data/biosoft/soft2024/conda/anaconda_23.4.7/envs/flask2024/lib/python3.9/site-packages/gunicorn/http/message.py", line 257, in __init__
    super().__init__(cfg, unreader, peer_addr)
  File "/data/biosoft/soft2024/conda/anaconda_23.4.7/envs/flask2024/lib/python3.9/site-packages/gunicorn/http/message.py", line 60, in __init__
    unused = self.parse(self.unreader)
  File "/data/biosoft/soft2024/conda/anaconda_23.4.7/envs/flask2024/lib/python3.9/site-packages/gunicorn/http/message.py", line 269, in parse
    self.get_data(unreader, buf, stop=True)
  File "/data/biosoft/soft2024/conda/anaconda_23.4.7/envs/flask2024/lib/python3.9/site-packages/gunicorn/http/message.py", line 260, in get_data
    data = unreader.read()
  File "/data/biosoft/soft2024/conda/anaconda_23.4.7/envs/flask2024/lib/python3.9/site-packages/gunicorn/http/unreader.py", line 37, in read
    d = self.chunk()
  File "/data/biosoft/soft2024/conda/anaconda_23.4.7/envs/flask2024/lib/python3.9/site-packages/gunicorn/http/unreader.py", line 64, in chunk
    return self.sock.recv(self.mxchunk)
  File "/data/biosoft/soft2024/conda/anaconda_23.4.7/envs/flask2024/lib/python3.9/site-packages/gunicorn/workers/base.py", line 203, in handle_abort
    sys.exit(1)
SystemExit: 1
[2024-05-27 17:53:50 +0800] [403644] [ERROR] Worker (pid:403744) was sent SIGHUP!
[2024-05-27 17:53:50 +0800] [403644] [ERROR] Worker (pid:403647) was sent SIGHUP!
[2024-05-27 17:53:50 +0800] [403644] [ERROR] Worker (pid:403743) was sent SIGHUP!
[2024-05-27 17:53:50 +0800] [403644] [ERROR] Worker (pid:403646) was sent SIGHUP!
[2024-05-27 17:53:50 +0800] [403644] [ERROR] Worker (pid:403648) was sent SIGHUP!
[2024-05-27 17:53:50 +0800] [403644] [ERROR] Worker (pid:403745) was sent SIGHUP!
[2024-05-27 17:53:50 +0800] [403644] [ERROR] Worker (pid:403746) was sent SIGHUP!
[2024-05-27 17:53:50 +0800] [403644] [ERROR] Worker (pid:404178) was sent SIGHUP!
[2024-05-27 17:53:50 +0800] [403644] [ERROR] Worker (pid:410000) was sent SIGTERM!
[2024-05-27 17:53:50 +0800] [403644] [ERROR] Worker (pid:409991) was sent SIGTERM!
[2024-05-27 17:53:50 +0800] [403644] [ERROR] Worker (pid:409998) was sent SIGTERM!
[2024-05-27 17:53:50 +0800] [403644] [ERROR] Worker (pid:410002) was sent SIGTERM!
[2024-05-27 17:53:50 +0800] [403644] [ERROR] Worker (pid:409993) was sent SIGTERM!
[2024-05-27 17:53:50 +0800] [403644] [ERROR] Worker (pid:410001) was sent SIGTERM!
[2024-05-27 17:53:50 +0800] [403644] [ERROR] Worker (pid:409995) was sent SIGTERM!
[2024-05-27 19:03:48,035] ERROR in app: Exception on /check/20240527190342-019e8006-d93e-4534-8364-8079d8f9183c [POST]
Traceback (most recent call last):
  File "/data/biosoft/soft2024/conda/anaconda_23.4.7/envs/flask2024/lib/python3.9/site-packages/flask/app.py", line 1473, in wsgi_app
    response = self.full_dispatch_request()
  File "/data/biosoft/soft2024/conda/anaconda_23.4.7/envs/flask2024/lib/python3.9/site-packages/flask/app.py", line 882, in full_dispatch_request
    rv = self.handle_user_exception(e)
  File "/data/biosoft/soft2024/conda/anaconda_23.4.7/envs/flask2024/lib/python3.9/site-packages/flask/app.py", line 880, in full_dispatch_request
    rv = self.dispatch_request()
  File "/data/biosoft/soft2024/conda/anaconda_23.4.7/envs/flask2024/lib/python3.9/site-packages/flask/app.py", line 865, in dispatch_request
    return self.ensure_sync(self.view_functions[rule.endpoint])(**view_args)  # type: ignore[no-any-return]
  File "/data/cailab/flask2024/demo/blueprint/biology.py", line 59, in check
    fastqs = get_fq_list(selected_folder, info["mode"] != "single")
  File "/data/cailab/flask2024/demo/blueprint/modules/utils.py", line 69, in get_fq_list
    for file in os.listdir(indir):
FileNotFoundError: [Errno 2] No such file or directory: 'no input'
